Workbook

Sheet Inputs
A1: Trading Strategy Simulator (Scenario Mixture + Monte Carlo)
A3: Key inputs (edit blue text cells)
A4: Inputs | E4: Per-market scenarios (edit blue cells)
A5: Start date | B5: 46055 | C5: Used for the path simulation sheet. | E5: Scenario | F5: Probability | G5: Mean return (%) | H5: Std dev (%) | I5: Cum. prob | J5: Lower bound
A6: Trading days (horizon) | B6: 60 | C6: Number of trading days simulated in Path_Sim. | E6: clean_win | F6: 0.6 | G6: 7.91 | H6: 0.99 | I6: =F6 | J6: 0
A7: Starting capital ($) | B7: 1000 | C7: Bankroll used for Path_Sim + P&L conversion. | E7: 1_stop_loss | F7: 0.13 | G7: 2.56 | H7: 1.31 | I7: =I6+F7 | J7: =I6
A8: Markets per day | B8: 6 | C8: Per day; Daily_MC uses up to 10 markets, only first M are active. | E8: 2_stop_losses | F8: 0.13 | G8: -6.76 | H8: 1.35 | I8: =I7+F8 | J8: =I7
A9: Target capital ($) | B9: 10000 | C9: Used for 'Hit target?' tracking. | E9: 3_stop_losses | F9: 0.13 | G9: -2.63 | H9: 1.99 | I9: =I8+F9 | J9: =I8
A10: Daily profit skim threshold ($, optional) | B10: 10000 | C10: If Skim mode ON, profits above threshold are auto-withdrawn each day.
A11: Skim mode (0=Off, 1=On) | B11: 1 | C11: 1=skim ON. Set to 0 to compound.
A12: Return clamp (%, 0=Off) | B12: 25 | C12: Caps each market return to +/- clamp% to avoid extreme Normal tails.
A13: Daily MC simulations (rows used) | B13: 1000 | C13: Summary stats use first N rows in Daily_MC.
A16: Quick checks / derived metrics
A17: Probabilities sum | B17: =SUM(F6:F9)
A18: Expected return per market (%) | B18: =SUMPRODUCT(F6:F9,G6:G9)
A19: Variance per market (approx, %^2) | B19: =SUMPRODUCT(F6:F9,(H6:H9^2 + (G6:G9-$B$18)^2))
A20: Std dev per market (approx, %) | B20: =SQRT($B$19)
A21: Expected daily return (%, equal split) | B21: =$B$18
A22: Expected daily P&L ($) | B22: =$B$7*($B$21/100)
A24: Scenario sanity | B24: =IF(ABS($B$17-1)<0.0001,"OK","CHECK: probs not 100%")

Sheet Daily_MC
A1: Daily Monte Carlo (one-day distribution, using per-market scenario mixture)
A3: Markets/day | B3: =Inputs!$B$8 | D3: Start capital ($) | E3: =Inputs!$B$7 | G3: Sim rows used | H3: =Inputs!$B$13 | K3: Summary (uses first N sims)
K4: Mean daily return (%) | L4: =AVERAGE($B$6:$B$5005)
A5: Sim # | B5: Daily return (%) | C5: Daily return (dec) | D5: Daily P&L ($) | E5: Profitable? | F5: M1 return (%) | G5: M2 return (%) | H5: M3 return (%) | I5: M4 return (%) | J5: M5 return (%) | K5: Std dev daily return (%) | L5: =STDEV.S($B$6:$B$5005) | M5: M8 return (%) | N5: M9 return (%) | O5: M10 return (%) | P5: u1 | Q5: u2 | R5: u3 | S5: u4 | T5: u5 | U5: u6 | V5: u7 | W5: u8 | X5: u9 | Y5: u10
A6: 1 | B6: =IF($A6<=Inputs!$B$13,IF(Inputs!$B$8>0,SUM(F6:O6)/Inputs!$B$8,0),"") | C6: =IF($A6<=Inputs!$B$13,B6/100,"") | D6: =IF($A6<=Inputs!$B$13,C6*Inputs!$B$7,"") | E6: =IF($A6<=Inputs!$B$13,IF(D6>0,1,0),"") | F6: =IF($A6<=Inputs!$B$13,IF(1<=Inputs!$B$8,IF(Inputs!$B$12>0,MAX(MIN(NORM.INV(RAND(),LOOKUP(P6,Inputs!$J$6:$J$9,Inputs!$G$6:$G$9),LOOKUP(P6,Inputs!$J$6:$J$9,Inputs!$H$6:$H$9)),Inputs!$B$12),-Inputs!$B$12),NORM.INV(RAND(),LOOKUP(P6,Inputs!$J$6:$J$9,Inputs!$G$6:$G$9),LOOKUP(P6,Inputs!$J$6:$J$9,Inputs!$H$6:$H$9))),0),"" ) | G6: =IF($A6<=Inputs!$B$13,IF(2<=Inputs!$B$8,IF(Inputs!$B$12>0,MAX(MIN(NORM.INV(RAND(),LOOKUP(Q6,Inputs!$J$6:$J$9,Inputs!$G$6:$G$9),LOOKUP(Q6,Inputs!$J$6:$J$9,Inputs!$H$6:$H$9)),Inputs!$B$12),-Inputs!$B$12),NORM.INV(RAND(),LOOKUP(Q6,Inputs!$J$6:$J$9,Inputs!$G$6:$G$9),LOOKUP(Q6,Inputs!$J$6:$J$9,Inputs!$H$6:$H$9))),0),"" ) | H6: =IF($A6<=Inputs!$B$13,IF(3<=Inputs!$B$8,IF(Inputs!$B$12>0,MAX(MIN(NORM.INV(RAND(),LOOKUP(R6,Inputs!$J$6:$J$9,Inputs!$G$6:$G$9),LOOKUP(R6,Inputs!$J$6:$J$9,Inputs!$H$6:$H$9)),Inputs!$B$12),-Inputs!$B$12),NORM.INV(RAND(),LOOKUP(R6,Inputs!$J$6:$J$9,Inputs!$G$6:$G$9),LOOKUP(R6,Inputs!$J$6:$J$9,Inputs!$H$6:$H$9))),0),"" ) | I6: =IF($A6<=Inputs!$B$13,IF(4<=Inputs!$B$8,IF(Inputs!$B$12>0,MAX(MIN(NORM.INV(RAND(),LOOKUP(S6,Inputs!$J$6:$J$9,Inputs!$G$6:$G$9),LOOKUP(S6,Inputs!$J$6:$J$9,Inputs!$H$6:$H$9)),Inputs!$B$12),-Inputs!$B$12),NORM.INV(RAND(),LOOKUP(S6,Inputs!$J$6:$J$9,Inputs!$G$6:$G$9),LOOKUP(S6,Inputs!$J$6:$J$9,Inputs!$H$6:$H$9))),0),"" ) | J6: =IF($A6<=Inputs!$B$13,IF(5<=Inputs!$B$8,IF(Inputs!$B$12>0,MAX(MIN(NORM.INV(RAND(),LOOKUP(T6,Inputs!$J$6:$J$9,Inputs!$G$6:$G$9),LOOKUP(T6,Inputs!$J$6:$J$9,Inputs!$H$6:$H$9)),Inputs!$B$12),-Inputs!$B$12),NORM.INV(RAND(),LOOKUP(T6,Inputs!$J$6:$J$9,Inputs!$G$6:$G$9),LOOKUP(T6,Inputs!$J$6:$J$9,Inputs!$H$6:$H$9))),0),"" ) | K6: =IF($A6<=Inputs!$B$13,IF(6<=Inputs!$B$8,IF(Inputs!$B$12>0,MAX(MIN(NORM.INV(RAND(),LOOKUP(U6,Inputs!$J$6:$J$9,Inputs!$G$6:$G$9),LOOKUP(U6,Inputs!$J$6:$J$9,Inputs!$H$6:$H$9)),Inputs!$B$12),-Inputs!$B$12),NORM.INV(RAND(),LOOKUP(U6,Inputs!$J$6:$J$9,Inputs!$G$6:$G$9),LOOKUP(U6,Inputs!$J$6:$J$9,Inputs!$H$6:$H$9))),0),"" ) | L6: =PERCENTILE.INC($B$6:$B$5005,0.05) | M6: =IF($A6<=Inputs!$B$13,IF(8<=Inputs!$B$8,IF(Inputs!$B$12>0,MAX(MIN(NORM.INV(RAND(),LOOKUP(W6,Inputs!$J$6:$J$9,Inputs!$G$6:$G$9),LOOKUP(W6,Inputs!$J$6:$J$9,Inputs!$H$6:$H$9)),Inputs!$B$12),-Inputs!$B$12),NORM.INV(RAND(),LOOKUP(W6,Inputs!$J$6:$J$9,Inputs!$G$6:$G$9),LOOKUP(W6,Inputs!$J$6:$J$9,Inputs!$H$6:$H$9))),0),"" ) | N6: =IF($A6<=Inputs!$B$13,IF(9<=Inputs!$B$8,IF(Inputs!$B$12>0,MAX(MIN(NORM.INV(RAND(),LOOKUP(X6,Inputs!$J$6:$J$9,Inputs!$G$6:$G$9),LOOKUP(X6,Inputs!$J$6:$J$9,Inputs!$H$6:$H$9)),Inputs!$B$12),-Inputs!$B$12),NORM.INV(RAND(),LOOKUP(X6,Inputs!$J$6:$J$9,Inputs!$G$6:$G$9),LOOKUP(X6,Inputs!$J$6:$J$9,Inputs!$H$6:$H$9))),0),"" ) | O6: =IF($A6<=Inputs!$B$13,IF(10<=Inputs!$B$8,IF(Inputs!$B$12>0,MAX(MIN(NORM.INV(RAND(),LOOKUP(Y6,Inputs!$J$6:$J$9,Inputs!$G$6:$G$9),LOOKUP(Y6,Inputs!$J$6:$J$9,Inputs!$H$6:$H$9)),Inputs!$B$12),-Inputs!$B$12),NORM.INV(RAND(),LOOKUP(Y6,Inputs!$J$6:$J$9,Inputs!$G$6:$G$9),LOOKUP(Y6,Inputs!$J$6:$J$9,Inputs!$H$6:$H$9))),0),"" ) | P6: =IF($A6<=Inputs!$B$13,RAND(),"") | Q6: =IF($A6<=Inputs!$B$13,RAND(),"") | R6: =IF($A6<=Inputs!$B$13,RAND(),"") | S6: =IF($A6<=Inputs!$B$13,RAND(),"") | T6: =IF($A6<=Inputs!$B$13,RAND(),"") | U6: =IF($A6<=Inputs!$B$13,RAND(),"") | V6: =IF($A6<=Inputs!$B$13,RAND(),"") | W6: =IF($A6<=Inputs!$B$13,RAND(),"") | ... Y6: =IF($A6<=Inputs!$B$13,RAND(),"")
A7: 2 | B7: =IF($A7<=Inputs!$B$13,IF(Inputs!$B$8>0,SUM(F7:O7)/Inputs!$B$8,0),"") | C7: =IF($A7<=Inputs!$B$13,B7/100,"") | D7: =IF($A7<=Inputs!$B$13,C7*Inputs!$B$7,"") | E7: =IF($A7<=Inputs!$B$13,IF(D7>0,1,0),"") | F7: =IF($A7<=Inputs!$B$13,IF(1<=Inputs!$B$8,IF(Inputs!$B$12>0,MAX(MIN(NORM.INV(RAND(),LOOKUP(P7,Inputs!$J$6:$J$9,Inputs!$G$6:$G$9),LOOKUP(P7,Inputs!$J$6:$J$9,Inputs!$H$6:$H$9)),Inputs!$B$12),-Inputs!$B$12),NORM.INV(RAND(),LOOKUP(P7,Inputs!$J$6:$J$9,Inputs!$G$6:$G$9),LOOKUP(P7,Inputs!$J$6:$J$9,Inputs!$H$6:$H$9))),0),"" ) | G7: =IF($A7<=Inputs!$B$13,IF(2<=Inputs!$B$8,IF(Inputs!$B$12>0,MAX(MIN(NORM.INV(RAND(),LOOKUP(Q7,Inputs!$J$6:$J$9,Inputs!$G$6:$G$9),LOOKUP(Q7,Inputs!$J$6:$J$9,Inputs!$H$6:$H$9)),Inputs!$B$12),-Inputs!$B$12),NORM.INV(RAND(),LOOKUP(Q7,Inputs!$J$6:$J$9,Inputs!$G$6:$G$9),LOOKUP(Q7,Inputs!$J$6:$J$9,Inputs!$H$6:$H$9))),0),"" ) | H7: =IF($A7<=Inputs!$B$13,IF(3<=Inputs!$B$8,IF(Inputs!$B$12>0,MAX(MIN(NORM.INV(RAND(),LOOKUP(R7,Inputs!$J$6:$J$9,Inputs!$G$6:$G$9),LOOKUP(R7,Inputs!$J$6:$J$9,Inputs!$H$6:$H$9)),Inputs!$B$12),-Inputs!$B$12),NORM.INV(RAND(),LOOKUP(R7,Inputs!$J$6:$J$9,Inputs!$G$6:$G$9),LOOKUP(R7,Inputs!$J$6:$J$9,Inputs!$H$6:$H$9))),0),"" ) | I7: =IF($A7<=Inputs!$B$13,IF(4<=Inputs!$B$8,IF(Inputs!$B$12>0,MAX(MIN(NORM.INV(RAND(),LOOKUP(S7,Inputs!$J$6:$J$9,Inputs!$G$6:$G$9),LOOKUP(S7,Inputs!$J$6:$J$9,Inputs!$H$6:$H$9)),Inputs!$B$12),-Inputs!$B$12),NORM.INV(RAND(),LOOKUP(S7,Inputs!$J$6:$J$9,Inputs!$G$6:$G$9),LOOKUP(S7,Inputs!$J$6:$J$9,Inputs!$H$6:$H$9))),0),"" ) | J7: =IF($A7<=Inputs!$B$13,IF(5<=Inputs!$B$8,IF(Inputs!$B$12>0,MAX(MIN(NORM.INV(RAND(),LOOKUP(T7,Inputs!$J$6:$J$9,Inputs!$G$6:$G$9),LOOKUP(T7,Inputs!$J$6:$J$9,Inputs!$H$6:$H$9)),Inputs!$B$12),-Inputs!$B$12),NORM.INV(RAND(),LOOKUP(T7,Inputs!$J$6:$J$9,Inputs!$G$6:$G$9),LOOKUP(T7,Inputs!$J$6:$J$9,Inputs!$H$6:$H$9))),0),"" ) | K7: =IF($A7<=Inputs!$B$13,IF(6<=Inputs!$B$8,IF(Inputs!$B$12>0,MAX(MIN(NORM.INV(RAND(),LOOKUP(U7,Inputs!$J$6:$J$9,Inputs!$G$6:$G$9),LOOKUP(U7,Inputs!$J$6:$J$9,Inputs!$H$6:$H$9)),Inputs!$B$12),-Inputs!$B$12),NORM.INV(RAND(),LOOKUP(U7,Inputs!$J$6:$J$9,Inputs!$G$6:$G$9),LOOKUP(U7,Inputs!$J$6:$J$9,Inputs!$H$6:$H$9))),0),"" ) | L7: =PERCENTILE.INC($B$6:$B$5005,0.50) | M7: =IF($A7<=Inputs!$B$13,IF(8<=Inputs!$B$8,IF(Inputs!$B$12>0,MAX(MIN(NORM.INV(RAND(),LOOKUP(W7,Inputs!$J$6:$J$9,Inputs!$G$6:$G$9),LOOKUP(W7,Inputs!$J$6:$J$9,Inputs!$H$6:$H$9)),Inputs!$B$12),-Inputs!$B$12),NORM.INV(RAND(),LOOKUP(W7,Inputs!$J$6:$J$9,Inputs!$G$6:$G$9),LOOKUP(W7,Inputs!$J$6:$J$9,Inputs!$H$6:$H$9))),0),"" ) | N7: =IF($A7<=Inputs!$B$13,IF(9<=Inputs!$B$8,IF(Inputs!$B$12>0,MAX(MIN(NORM.INV(RAND(),LOOKUP(X7,Inputs!$J$6:$J$9,Inputs!$G$6:$G$9),LOOKUP(X7,Inputs!$J$6:$J$9,Inputs!$H$6:$H$9)),Inputs!$B$12),-Inputs!$B$12),NORM.INV(RAND(),LOOKUP(X7,Inputs!$J$6:$J$9,Inputs!$G$6:$G$9),LOOKUP(X7,Inputs!$J$6:$J$9,Inputs!$H$6:$H$9))),0),"" ) | O7: =IF($A7<=Inputs!$B$13,IF(10<=Inputs!$B$8,IF(Inputs!$B$12>0,MAX(MIN(NORM.INV(RAND(),LOOKUP(Y7,Inputs!$J$6:$J$9,Inputs!$G$6:$G$9),LOOKUP(Y7,Inputs!$J$6:$J$9,Inputs!$H$6:$H$9)),Inputs!$B$12),-Inputs!$B$12),NORM.INV(RAND(),LOOKUP(Y7,Inputs!$J$6:$J$9,Inputs!$G$6:$G$9),LOOKUP(Y7,Inputs!$J$6:$J$9,Inputs!$H$6:$H$9))),0),"" ) | P7: =IF($A7<=Inputs!$B$13,RAND(),"") | Q7: =IF($A7<=Inputs!$B$13,RAND(),"") | R7: =IF($A7<=Inputs!$B$13,RAND(),"") | S7: =IF($A7<=Inputs!$B$13,RAND(),"") | T7: =IF($A7<=Inputs!$B$13,RAND(),"") | U7: =IF($A7<=Inputs!$B$13,RAND(),"") | V7: =IF($A7<=Inputs!$B$13,RAND(),"") | W7: =IF($A7<=Inputs!$B$13,RAND(),"") | ... Y7: =IF($A7<=Inputs!$B$13,RAND(),"")
A8: 3 | B8: =IF($A8<=Inputs!$B$13,IF(Inputs!$B$8>0,SUM(F8:O8)/Inputs!$B$8,0),"") | C8: =IF($A8<=Inputs!$B$13,B8/100,"") | D8: =IF($A8<=Inputs!$B$13,C8*Inputs!$B$7,"") | E8: =IF($A8<=Inputs!$B$13,IF(D8>0,1,0),"") | F8: =IF($A8<=Inputs!$B$13,IF(1<=Inputs!$B$8,IF(Inputs!$B$12>0,MAX(MIN(NORM.INV(RAND(),LOOKUP(P8,Inputs!$J$6:$J$9,Inputs!$G$6:$G$9),LOOKUP(P8,Inputs!$J$6:$J$9,Inputs!$H$6:$H$9)),Inputs!$B$12),-Inputs!$B$12),NORM.INV(RAND(),LOOKUP(P8,Inputs!$J$6:$J$9,Inputs!$G$6:$G$9),LOOKUP(P8,Inputs!$J$6:$J$9,Inputs!$H$6:$H$9))),0),"" ) | G8: =IF($A8<=Inputs!$B$13,IF(2<=Inputs!$B$8,IF(Inputs!$B$12>0,MAX(MIN(NORM.INV(RAND(),LOOKUP(Q8,Inputs!$J$6:$J$9,Inputs!$G$6:$G$9),LOOKUP(Q8,Inputs!$J$6:$J$9,Inputs!$H$6:$H$9)),Inputs!$B$12),-Inputs!$B$12),NORM.INV(RAND(),LOOKUP(Q8,Inputs!$J$6:$J$9,Inputs!$G$6:$G$9),LOOKUP(Q8,Inputs!$J$6:$J$9,Inputs!$H$6:$H$9))),0),"" ) | H8: =IF($A8<=Inputs!$B$13,IF(3<=Inputs!$B$8,IF(Inputs!$B$12>0,MAX(MIN(NORM.INV(RAND(),LOOKUP(R8,Inputs!$J$6:$J$9,Inputs!$G$6:$G$9),LOOKUP(R8,Inputs!$J$6:$J$9,Inputs!$H$6:$H$9)),Inputs!$B$12),-Inputs!$B$12),NORM.INV(RAND(),LOOKUP(R8,Inputs!$J$6:$J$9,Inputs!$G$6:$G$9),LOOKUP(R8,Inputs!$J$6:$J$9,Inputs!$H$6:$H$9))),0),"" ) | I8: =IF($A8<=Inputs!$B$13,IF(4<=Inputs!$B$8,IF(Inputs!$B$12>0,MAX(MIN(NORM.INV(RAND(),LOOKUP(S8,Inputs!$J$6:$J$9,Inputs!$G$6:$G$9),LOOKUP(S8,Inputs!$J$6:$J$9,Inputs!$H$6:$H$9)),Inputs!$B$12),-Inputs!$B$12),NORM.INV(RAND(),LOOKUP(S8,Inputs!$J$6:$J$9,Inputs!$G$6:$G$9),LOOKUP(S8,Inputs!$J$6:$J$9,Inputs!$H$6:$H$9))),0),"" ) | J8: =IF($A8<=Inputs!$B$13,IF(5<=Inputs!$B$8,IF(Inputs!$B$12>0,MAX(MIN(NORM.INV(RAND(),LOOKUP(T8,Inputs!$J$6:$J$9,Inputs!$G$6:$G$9),LOOKUP(T8,Inputs!$J$6:$J$9,Inputs!$H$6:$H$9)),Inputs!$B$12),-Inputs!$B$12),NORM.INV(RAND(),LOOKUP(T8,Inputs!$J$6:$J$9,Inputs!$G$6:$G$9),LOOKUP(T8,Inputs!$J$6:$J$9,Inputs!$H$6:$H$9))),0),"" ) | K8: =IF($A8<=Inputs!$B$13,IF(6<=Inputs!$B$8,IF(Inputs!$B$12>0,MAX(MIN(NORM.INV(RAND(),LOOKUP(U8,Inputs!$J$6:$J$9,Inputs!$G$6:$G$9),LOOKUP(U8,Inputs!$J$6:$J$9,Inputs!$H$6:$H$9)),Inputs!$B$12),-Inputs!$B$12),NORM.INV(RAND(),LOOKUP(U8,Inputs!$J$6:$J$9,Inputs!$G$6:$G$9),LOOKUP(U8,Inputs!$J$6:$J$9,Inputs!$H$6:$H$9))),0),"" ) | L8: =PERCENTILE.INC($B$6:$B$5005,0.95) | M8: =IF($A8<=Inputs!$B$13,IF(8<=Inputs!$B$8,IF(Inputs!$B$12>0,MAX(MIN(NORM.INV(RAND(),LOOKUP(W8,Inputs!$J$6:$J$9,Inputs!$G$6:$G$9),LOOKUP(W8,Inputs!$J$6:$J$9,Inputs!$H$6:$H$9)),Inputs!$B$12),-Inputs!$B$12),NORM.INV(RAND(),LOOKUP(W8,Inputs!$J$6:$J$9,Inputs!$G$6:$G$9),LOOKUP(W8,Inputs!$J$6:$J$9,Inputs!$H$6:$H$9))),0),"" ) | N8: =IF($A8<=Inputs!$B$13,IF(9<=Inputs!$B$8,IF(Inputs!$B$12>0,MAX(MIN(NORM.INV(RAND(),LOOKUP(X8,Inputs!$J$6:$J$9,Inputs!$G$6:$G$9),LOOKUP(X8,Inputs!$J$6:$J$9,Inputs!$H$6:$H$9)),Inputs!$B$12),-Inputs!$B$12),NORM.INV(RAND(),LOOKUP(X8,Inputs!$J$6:$J$9,Inputs!$G$6:$G$9),LOOKUP(X8,Inputs!$J$6:$J$9,Inputs!$H$6:$H$9))),0),"" ) | O8: =IF($A8<=Inputs!$B$13,IF(10<=Inputs!$B$8,IF(Inputs!$B$12>0,MAX(MIN(NORM.INV(RAND(),LOOKUP(Y8,Inputs!$J$6:$J$9,Inputs!$G$6:$G$9),LOOKUP(Y8,Inputs!$J$6:$J$9,Inputs!$H$6:$H$9)),Inputs!$B$12),-Inputs!$B$12),NORM.INV(RAND(),LOOKUP(Y8,Inputs!$J$6:$J$9,Inputs!$G$6:$G$9),LOOKUP(Y8,Inputs!$J$6:$J$9,Inputs!$H$6:$H$9))),0),"" ) | P8: =IF($A8<=Inputs!$B$13,RAND(),"") | Q8: =IF($A8<=Inputs!$B$13,RAND(),"") | R8: =IF($A8<=Inputs!$B$13,RAND(),"") | S8: =IF($A8<=Inputs!$B$13,RAND(),"") | T8: =IF($A8<=Inputs!$B$13,RAND(),"") | U8: =IF($A8<=Inputs!$B$13,RAND(),"") | V8: =IF($A8<=Inputs!$B$13,RAND(),"") | W8: =IF($A8<=Inputs!$B$13,RAND(),"") | ... Y8: =IF($A8<=Inputs!$B$13,RAND(),"")
A9: 4 | B9: =IF($A9<=Inputs!$B$13,IF(Inputs!$B$8>0,SUM(F9:O9)/Inputs!$B$8,0),"") | C9: =IF($A9<=Inputs!$B$13,B9/100,"") | D9: =IF($A9<=Inputs!$B$13,C9*Inputs!$B$7,"") | E9: =IF($A9<=Inputs!$B$13,IF(D9>0,1,0),"") | F9: =IF($A9<=Inputs!$B$13,IF(1<=Inputs!$B$8,IF(Inputs!$B$12>0,MAX(MIN(NORM.INV(RAND(),LOOKUP(P9,Inputs!$J$6:$J$9,Inputs!$G$6:$G$9),LOOKUP(P9,Inputs!$J$6:$J$9,Inputs!$H$6:$H$9)),Inputs!$B$12),-Inputs!$B$12),NORM.INV(RAND(),LOOKUP(P9,Inputs!$J$6:$J$9,Inputs!$G$6:$G$9),LOOKUP(P9,Inputs!$J$6:$J$9,Inputs!$H$6:$H$9))),0),"" ) | G9: =IF($A9<=Inputs!$B$13,IF(2<=Inputs!$B$8,IF(Inputs!$B$12>0,MAX(MIN(NORM.INV(RAND(),LOOKUP(Q9,Inputs!$J$6:$J$9,Inputs!$G$6:$G$9),LOOKUP(Q9,Inputs!$J$6:$J$9,Inputs!$H$6:$H$9)),Inputs!$B$12),-Inputs!$B$12),NORM.INV(RAND(),LOOKUP(Q9,Inputs!$J$6:$J$9,Inputs!$G$6:$G$9),LOOKUP(Q9,Inputs!$J$6:$J$9,Inputs!$H$6:$H$9))),0),"" ) | H9: =IF($A9<=Inputs!$B$13,IF(3<=Inputs!$B$8,IF(Inputs!$B$12>0,MAX(MIN(NORM.INV(RAND(),LOOKUP(R9,Inputs!$J$6:$J$9,Inputs!$G$6:$G$9),LOOKUP(R9,Inputs!$J$6:$J$9,Inputs!$H$6:$H$9)),Inputs!$B$12),-Inputs!$B$12),NORM.INV(RAND(),LOOKUP(R9,Inputs!$J$6:$J$9,Inputs!$G$6:$G$9),LOOKUP(R9,Inputs!$J$6:$J$9,Inputs!$H$6:$H$9))),0),"" ) | I9: =IF($A9<=Inputs!$B$13,IF(4<=Inputs!$B$8,IF(Inputs!$B$12>0,MAX(MIN(NORM.INV(RAND(),LOOKUP(S9,Inputs!$J$6:$J$9,Inputs!$G$6:$G$9),LOOKUP(S9,Inputs!$J$6:$J$9,Inputs!$H$6:$H$9)),Inputs!$B$12),-Inputs!$B$12),NORM.INV(RAND(),LOOKUP(S9,Inputs!$J$6:$J$9,Inputs!$G$6:$G$9),LOOKUP(S9,Inputs!$J$6:$J$9,Inputs!$H$6:$H$9))),0),"" ) | J9: =IF($A9<=Inputs!$B$13,IF(5<=Inputs!$B$8,IF(Inputs!$B$12>0,MAX(MIN(NORM.INV(RAND(),LOOKUP(T9,Inputs!$J$6:$J$9,Inputs!$G$6:$G$9),LOOKUP(T9,Inputs!$J$6:$J$9,Inputs!$H$6:$H$9)),Inputs!$B$12),-Inputs!$B$12),NORM.INV(RAND(),LOOKUP(T9,Inputs!$J$6:$J$9,Inputs!$G$6:$G$9),LOOKUP(T9,Inputs!$J$6:$J$9,Inputs!$H$6:$H$9))),0),"" ) | K9: =IF($A9<=Inputs!$B$13,IF(6<=Inputs!$B$8,IF(Inputs!$B$12>0,MAX(MIN(NORM.INV(RAND(),LOOKUP(U9,Inputs!$J$6:$J$9,Inputs!$G$6:$G$9),LOOKUP(U9,Inputs!$J$6:$J$9,Inputs!$H$6:$H$9)),Inputs!$B$12),-Inputs!$B$12),NORM.INV(RAND(),LOOKUP(U9,Inputs!$J$6:$J$9,Inputs!$G$6:$G$9),LOOKUP(U9,Inputs!$J$6:$J$9,Inputs!$H$6:$H$9))),0),"" ) | L9: =AVERAGE($E$6:$E$5005) | M9: =IF($A9<=Inputs!$B$13,IF(8<=Inputs!$B$8,IF(Inputs!$B$12>0,MAX(MIN(NORM.INV(RAND(),LOOKUP(W9,Inputs!$J$6:$J$9,Inputs!$G$6:$G$9),LOOKUP(W9,Inputs!$J$6:$J$9,Inputs!$H$6:$H$9)),Inputs!$B$12),-Inputs!$B$12),NORM.INV(RAND(),LOOKUP(W9,Inputs!$J$6:$J$9,Inputs!$G$6:$G$9),LOOKUP(W9,Inputs!$J$6:$J$9,Inputs!$H$6:$H$9))),0),"" ) | N9: =IF($A9<=Inputs!$B$13,IF(9<=Inputs!$B$8,IF(Inputs!$B$12>0,MAX(MIN(NORM.INV(RAND(),LOOKUP(X9,Inputs!$J$6:$J$9,Inputs!$G$6:$G$9),LOOKUP(X9,Inputs!$J$6:$J$9,Inputs!$H$6:$H$9)),Inputs!$B$12),-Inputs!$B$12),NORM.INV(RAND(),LOOKUP(X9,Inputs!$J$6:$J$9,Inputs!$G$6:$G$9),LOOKUP(X9,Inputs!$J$6:$J$9,Inputs!$H$6:$H$9))),0),"" ) | O9: =IF($A9<=Inputs!$B$13,IF(10<=Inputs!$B$8,IF(Inputs!$B$12>0,MAX(MIN(NORM.INV(RAND(),LOOKUP(Y9,Inputs!$J$6:$J$9,Inputs!$G$6:$G$9),LOOKUP(Y9,Inputs!$J$6:$J$9,Inputs!$H$6:$H$9)),Inputs!$B$12),-Inputs!$B$12),NORM.INV(RAND(),LOOKUP(Y9,Inputs!$J$6:$J$9,Inputs!$G$6:$G$9),LOOKUP(Y9,Inputs!$J$6:$J$9,Inputs!$H$6:$H$9))),0),"" ) | P9: =IF($A9<=Inputs!$B$13,RAND(),"") | Q9: =IF($A9<=Inputs!$B$13,RAND(),"") | R9: =IF($A9<=Inputs!$B$13,RAND(),"") | S9: =IF($A9<=Inputs!$B$13,RAND(),"") | T9: =IF($A9<=Inputs!$B$13,RAND(),"") | U9: =IF($A9<=Inputs!$B$13,RAND(),"") | V9: =IF($A9<=Inputs!$B$13,RAND(),"") | W9: =IF($A9<=Inputs!$B$13,RAND(),"") | ... Y9: =IF($A9<=Inputs!$B$13,RAND(),"")
A10: 5 | B10: =IF($A10<=Inputs!$B$13,IF(Inputs!$B$8>0,SUM(F10:O10)/Inputs!$B$8,0),"") | C10: =IF($A10<=Inputs!$B$13,B10/100,"") | D10: =IF($A10<=Inputs!$B$13,C10*Inputs!$B$7,"") | E10: =IF($A10<=Inputs!$B$13,IF(D10>0,1,0),"") | F10: =IF($A10<=Inputs!$B$13,IF(1<=Inputs!$B$8,IF(Inputs!$B$12>0,MAX(MIN(NORM.INV(RAND(),LOOKUP(P10,Inputs!$J$6:$J$9,Inputs!$G$6:$G$9),LOOKUP(P10,Inputs!$J$6:$J$9,Inputs!$H$6:$H$9)),Inputs!$B$12),-Inputs!$B$12),NORM.INV(RAND(),LOOKUP(P10,Inputs!$J$6:$J$9,Inputs!$G$6:$G$9),LOOKUP(P10,Inputs!$J$6:$J$9,Inputs!$H$6:$H$9))),0),"" ) | G10: =IF($A10<=Inputs!$B$13,IF(2<=Inputs!$B$8,IF(Inputs!$B$12>0,MAX(MIN(NORM.INV(RAND(),LOOKUP(Q10,Inputs!$J$6:$J$9,Inputs!$G$6:$G$9),LOOKUP(Q10,Inputs!$J$6:$J$9,Inputs!$H$6:$H$9)),Inputs!$B$12),-Inputs!$B$12),NORM.INV(RAND(),LOOKUP(Q10,Inputs!$J$6:$J$9,Inputs!$G$6:$G$9),LOOKUP(Q10,Inputs!$J$6:$J$9,Inputs!$H$6:$H$9))),0),"" ) | H10: =IF($A10<=Inputs!$B$13,IF(3<=Inputs!$B$8,IF(Inputs!$B$12>0,MAX(MIN(NORM.INV(RAND(),LOOKUP(R10,Inputs!$J$6:$J$9,Inputs!$G$6:$G$9),LOOKUP(R10,Inputs!$J$6:$J$9,Inputs!$H$6:$H$9)),Inputs!$B$12),-Inputs!$B$12),NORM.INV(RAND(),LOOKUP(R10,Inputs!$J$6:$J$9,Inputs!$G$6:$G$9),LOOKUP(R10,Inputs!$J$6:$J$9,Inputs!$H$6:$H$9))),0),"" ) | I10: =IF($A10<=Inputs!$B$13,IF(4<=Inputs!$B$8,IF(Inputs!$B$12>0,MAX(MIN(NORM.INV(RAND(),LOOKUP(S10,Inputs!$J$6:$J$9,Inputs!$G$6:$G$9),LOOKUP(S10,Inputs!$J$6:$J$9,Inputs!$H$6:$H$9)),Inputs!$B$12),-Inputs!$B$12),NORM.INV(RAND(),LOOKUP(S10,Inputs!$J$6:$J$9,Inputs!$G$6:$G$9),LOOKUP(S10,Inputs!$J$6:$J$9,Inputs!$H$6:$H$9))),0),"" ) | J10: =IF($A10<=Inputs!$B$13,IF(5<=Inputs!$B$8,IF(Inputs!$B$12>0,MAX(MIN(NORM.INV(RAND(),LOOKUP(T10,Inputs!$J$6:$J$9,Inputs!$G$6:$G$9),LOOKUP(T10,Inputs!$J$6:$J$9,Inputs!$H$6:$H$9)),Inputs!$B$12),-Inputs!$B$12),NORM.INV(RAND(),LOOKUP(T10,Inputs!$J$6:$J$9,Inputs!$G$6:$G$9),LOOKUP(T10,Inputs!$J$6:$J$9,Inputs!$H$6:$H$9))),0),"" ) | K10: =IF($A10<=Inputs!$B$13,IF(6<=Inputs!$B$8,IF(Inputs!$B$12>0,MAX(MIN(NORM.INV(RAND(),LOOKUP(U10,Inputs!$J$6:$J$9,Inputs!$G$6:$G$9),LOOKUP(U10,Inputs!$J$6:$J$9,Inputs!$H$6:$H$9)),Inputs!$B$12),-Inputs!$B$12),NORM.INV(RAND(),LOOKUP(U10,Inputs!$J$6:$J$9,Inputs!$G$6:$G$9),LOOKUP(U10,Inputs!$J$6:$J$9,Inputs!$H$6:$H$9))),0),"" ) | L10: =IF($A10<=Inputs!$B$13,IF(7<=Inputs!$B$8,IF(Inputs!$B$12>0,MAX(MIN(NORM.INV(RAND(),LOOKUP(V10,Inputs!$J$6:$J$9,Inputs!$G$6:$G$9),LOOKUP(V10,Inputs!$J$6:$J$9,Inputs!$H$6:$H$9)),Inputs!$B$12),-Inputs!$B$12),NORM.INV(RAND(),LOOKUP(V10,Inputs!$J$6:$J$9,Inputs!$G$6:$G$9),LOOKUP(V10,Inputs!$J$6:$J$9,Inputs!$H$6:$H$9))),0),"" ) | M10: =IF($A10<=Inputs!$B$13,IF(8<=Inputs!$B$8,IF(Inputs!$B$12>0,MAX(MIN(NORM.INV(RAND(),LOOKUP(W10,Inputs!$J$6:$J$9,Inputs!$G$6:$G$9),LOOKUP(W10,Inputs!$J$6:$J$9,Inputs!$H$6:$H$9)),Inputs!$B$12),-Inputs!$B$12),NORM.INV(RAND(),LOOKUP(W10,Inputs!$J$6:$J$9,Inputs!$G$6:$G$9),LOOKUP(W10,Inputs!$J$6:$J$9,Inputs!$H$6:$H$9))),0),"" ) | N10: =IF($A10<=Inputs!$B$13,IF(9<=Inputs!$B$8,IF(Inputs!$B$12>0,MAX(MIN(NORM.INV(RAND(),LOOKUP(X10,Inputs!$J$6:$J$9,Inputs!$G$6:$G$9),LOOKUP(X10,Inputs!$J$6:$J$9,Inputs!$H$6:$H$9)),Inputs!$B$12),-Inputs!$B$12),NORM.INV(RAND(),LOOKUP(X10,Inputs!$J$6:$J$9,Inputs!$G$6:$G$9),LOOKUP(X10,Inputs!$J$6:$J$9,Inputs!$H$6:$H$9))),0),"" ) | O10: =IF($A10<=Inputs!$B$13,IF(10<=Inputs!$B$8,IF(Inputs!$B$12>0,MAX(MIN(NORM.INV(RAND(),LOOKUP(Y10,Inputs!$J$6:$J$9,Inputs!$G$6:$G$9),LOOKUP(Y10,Inputs!$J$6:$J$9,Inputs!$H$6:$H$9)),Inputs!$B$12),-Inputs!$B$12),NORM.INV(RAND(),LOOKUP(Y10,Inputs!$J$6:$J$9,Inputs!$G$6:$G$9),LOOKUP(Y10,Inputs!$J$6:$J$9,Inputs!$H$6:$H$9))),0),"" ) | P10: =IF($A10<=Inputs!$B$13,RAND(),"") | Q10: =IF($A10<=Inputs!$B$13,RAND(),"") | R10: =IF($A10<=Inputs!$B$13,RAND(),"") | S10: =IF($A10<=Inputs!$B$13,RAND(),"") | T10: =IF($A10<=Inputs!$B$13,RAND(),"") | U10: =IF($A10<=Inputs!$B$13,RAND(),"") | V10: =IF($A10<=Inputs!$B$13,RAND(),"") | W10: =IF($A10<=Inputs!$B$13,RAND(),"") | ... Y10: =IF($A10<=Inputs!$B$13,RAND(),"")
A11: 6 | B11: =IF($A11<=Inputs!$B$13,IF(Inputs!$B$8>0,SUM(F11:O11)/Inputs!$B$8,0),"") | C11: =IF($A11<=Inputs!$B$13,B11/100,"") | D11: =IF($A11<=Inputs!$B$13,C11*Inputs!$B$7,"") | E11: =IF($A11<=Inputs!$B$13,IF(D11>0,1,0),"") | F11: =IF($A11<=Inputs!$B$13,IF(1<=Inputs!$B$8,IF(Inputs!$B$12>0,MAX(MIN(NORM.INV(RAND(),LOOKUP(P11,Inputs!$J$6:$J$9,Inputs!$G$6:$G$9),LOOKUP(P11,Inputs!$J$6:$J$9,Inputs!$H$6:$H$9)),Inputs!$B$12),-Inputs!$B$12),NORM.INV(RAND(),LOOKUP(P11,Inputs!$J$6:$J$9,Inputs!$G$6:$G$9),LOOKUP(P11,Inputs!$J$6:$J$9,Inputs!$H$6:$H$9))),0),"" ) | G11: =IF($A11<=Inputs!$B$13,IF(2<=Inputs!$B$8,IF(Inputs!$B$12>0,MAX(MIN(NORM.INV(RAND(),LOOKUP(Q11,Inputs!$J$6:$J$9,Inputs!$G$6:$G$9),LOOKUP(Q11,Inputs!$J$6:$J$9,Inputs!$H$6:$H$9)),Inputs!$B$12),-Inputs!$B$12),NORM.INV(RAND(),LOOKUP(Q11,Inputs!$J$6:$J$9,Inputs!$G$6:$G$9),LOOKUP(Q11,Inputs!$J$6:$J$9,Inputs!$H$6:$H$9))),0),"" ) | H11: =IF($A11<=Inputs!$B$13,IF(3<=Inputs!$B$8,IF(Inputs!$B$12>0,MAX(MIN(NORM.INV(RAND(),LOOKUP(R11,Inputs!$J$6:$J$9,Inputs!$G$6:$G$9),LOOKUP(R11,Inputs!$J$6:$J$9,Inputs!$H$6:$H$9)),Inputs!$B$12),-Inputs!$B$12),NORM.INV(RAND(),LOOKUP(R11,Inputs!$J$6:$J$9,Inputs!$G$6:$G$9),LOOKUP(R11,Inputs!$J$6:$J$9,Inputs!$H$6:$H$9))),0),"" ) | I11: =IF($A11<=Inputs!$B$13,IF(4<=Inputs!$B$8,IF(Inputs!$B$12>0,MAX(MIN(NORM.INV(RAND(),LOOKUP(S11,Inputs!$J$6:$J$9,Inputs!$G$6:$G$9),LOOKUP(S11,Inputs!$J$6:$J$9,Inputs!$H$6:$H$9)),Inputs!$B$12),-Inputs!$B$12),NORM.INV(RAND(),LOOKUP(S11,Inputs!$J$6:$J$9,Inputs!$G$6:$G$9),LOOKUP(S11,Inputs!$J$6:$J$9,Inputs!$H$6:$H$9))),0),"" ) | J11: =IF($A11<=Inputs!$B$13,IF(5<=Inputs!$B$8,IF(Inputs!$B$12>0,MAX(MIN(NORM.INV(RAND(),LOOKUP(T11,Inputs!$J$6:$J$9,Inputs!$G$6:$G$9),LOOKUP(T11,Inputs!$J$6:$J$9,Inputs!$H$6:$H$9)),Inputs!$B$12),-Inputs!$B$12),NORM.INV(RAND(),LOOKUP(T11,Inputs!$J$6:$J$9,Inputs!$G$6:$G$9),LOOKUP(T11,Inputs!$J$6:$J$9,Inputs!$H$6:$H$9))),0),"" ) | K11: =IF($A11<=Inputs!$B$13,IF(6<=Inputs!$B$8,IF(Inputs!$B$12>0,MAX(MIN(NORM.INV(RAND(),LOOKUP(U11,Inputs!$J$6:$J$9,Inputs!$G$6:$G$9),LOOKUP(U11,Inputs!$J$6:$J$9,Inputs!$H$6:$H$9)),Inputs!$B$12),-Inputs!$B$12),NORM.INV(RAND(),LOOKUP(U11,Inputs!$J$6:$J$9,Inputs!$G$6:$G$9),LOOKUP(U11,Inputs!$J$6:$J$9,Inputs!$H$6:$H$9))),0),"" ) | L11: =IF($A11<=Inputs!$B$13,IF(7<=Inputs!$B$8,IF(Inputs!$B$12>0,MAX(MIN(NORM.INV(RAND(),LOOKUP(V11,Inputs!$J$6:$J$9,Inputs!$G$6:$G$9),LOOKUP(V11,Inputs!$J$6:$J$9,Inputs!$H$6:$H$9)),Inputs!$B$12),-Inputs!$B$12),NORM.INV(RAND(),LOOKUP(V11,Inputs!$J$6:$J$9,Inputs!$G$6:$G$9),LOOKUP(V11,Inputs!$J$6:$J$9,Inputs!$H$6:$H$9))),0),"" ) | M11: =IF($A11<=Inputs!$B$13,IF(8<=Inputs!$B$8,IF(Inputs!$B$12>0,MAX(MIN(NORM.INV(RAND(),LOOKUP(W11,Inputs!$J$6:$J$9,Inputs!$G$6:$G$9),LOOKUP(W11,Inputs!$J$6:$J$9,Inputs!$H$6:$H$9)),Inputs!$B$12),-Inputs!$B$12),NORM.INV(RAND(),LOOKUP(W11,Inputs!$J$6:$J$9,Inputs!$G$6:$G$9),LOOKUP(W11,Inputs!$J$6:$J$9,Inputs!$H$6:$H$9))),0),"" ) | N11: =IF($A11<=Inputs!$B$13,IF(9<=Inputs!$B$8,IF(Inputs!$B$12>0,MAX(MIN(NORM.INV(RAND(),LOOKUP(X11,Inputs!$J$6:$J$9,Inputs!$G$6:$G$9),LOOKUP(X11,Inputs!$J$6:$J$9,Inputs!$H$6:$H$9)),Inputs!$B$12),-Inputs!$B$12),NORM.INV(RAND(),LOOKUP(X11,Inputs!$J$6:$J$9,Inputs!$G$6:$G$9),LOOKUP(X11,Inputs!$J$6:$J$9,Inputs!$H$6:$H$9))),0),"" ) | O11: =IF($A11<=Inputs!$B$13,IF(10<=Inputs!$B$8,IF(Inputs!$B$12>0,MAX(MIN(NORM.INV(RAND(),LOOKUP(Y11,Inputs!$J$6:$J$9,Inputs!$G$6:$G$9),LOOKUP(Y11,Inputs!$J$6:$J$9,Inputs!$H$6:$H$9)),Inputs!$B$12),-Inputs!$B$12),NORM.INV(RAND(),LOOKUP(Y11,Inputs!$J$6:$J$9,Inputs!$G$6:$G$9),LOOKUP(Y11,Inputs!$J$6:$J$9,Inputs!$H$6:$H$9))),0),"" ) | P11: =IF($A11<=Inputs!$B$13,RAND(),"") | Q11: =IF($A11<=Inputs!$B$13,RAND(),"") | R11: =IF($A11<=Inputs!$B$13,RAND(),"") | S11: =IF($A11<=Inputs!$B$13,RAND(),"") | T11: =IF($A11<=Inputs!$B$13,RAND(),"") | U11: =IF($A11<=Inputs!$B$13,RAND(),"") | V11: =IF($A11<=Inputs!$B$13,RAND(),"") | W11: =IF($A11<=Inputs!$B$13,RAND(),"") | ... Y11: =IF($A11<=Inputs!$B$13,RAND(),"")
A12: 7 | B12: =IF($A12<=Inputs!$B$13,IF(Inputs!$B$8>0,SUM(F12:O12)/Inputs!$B$8,0),"") | C12: =IF($A12<=Inputs!$B$13,B12/100,"") | D12: =IF($A12<=Inputs!$B$13,C12*Inputs!$B$7,"") | E12: =IF($A12<=Inputs!$B$13,IF(D12>0,1,0),"") | F12: =IF($A12<=Inputs!$B$13,IF(1<=Inputs!$B$8,IF(Inputs!$B$12>0,MAX(MIN(NORM.INV(RAND(),LOOKUP(P12,Inputs!$J$6:$J$9,Inputs!$G$6:$G$9),LOOKUP(P12,Inputs!$J$6:$J$9,Inputs!$H$6:$H$9)),Inputs!$B$12),-Inputs!$B$12),NORM.INV(RAND(),LOOKUP(P12,Inputs!$J$6:$J$9,Inputs!$G$6:$G$9),LOOKUP(P12,Inputs!$J$6:$J$9,Inputs!$H$6:$H$9))),0),"" ) | G12: =IF($A12<=Inputs!$B$13,IF(2<=Inputs!$B$8,IF(Inputs!$B$12>0,MAX(MIN(NORM.INV(RAND(),LOOKUP(Q12,Inputs!$J$6:$J$9,Inputs!$G$6:$G$9),LOOKUP(Q12,Inputs!$J$6:$J$9,Inputs!$H$6:$H$9)),Inputs!$B$12),-Inputs!$B$12),NORM.INV(RAND(),LOOKUP(Q12,Inputs!$J$6:$J$9,Inputs!$G$6:$G$9),LOOKUP(Q12,Inputs!$J$6:$J$9,Inputs!$H$6:$H$9))),0),"" ) | H12: =IF($A12<=Inputs!$B$13,IF(3<=Inputs!$B$8,IF(Inputs!$B$12>0,MAX(MIN(NORM.INV(RAND(),LOOKUP(R12,Inputs!$J$6:$J$9,Inputs!$G$6:$G$9),LOOKUP(R12,Inputs!$J$6:$J$9,Inputs!$H$6:$H$9)),Inputs!$B$12),-Inputs!$B$12),NORM.INV(RAND(),LOOKUP(R12,Inputs!$J$6:$J$9,Inputs!$G$6:$G$9),LOOKUP(R12,Inputs!$J$6:$J$9,Inputs!$H$6:$H$9))),0),"" ) | I12: =IF($A12<=Inputs!$B$13,IF(4<=Inputs!$B$8,IF(Inputs!$B$12>0,MAX(MIN(NORM.INV(RAND(),LOOKUP(S12,Inputs!$J$6:$J$9,Inputs!$G$6:$G$9),LOOKUP(S12,Inputs!$J$6:$J$9,Inputs!$H$6:$H$9)),Inputs!$B$12),-Inputs!$B$12),NORM.INV(RAND(),LOOKUP(S12,Inputs!$J$6:$J$9,Inputs!$G$6:$G$9),LOOKUP(S12,Inputs!$J$6:$J$9,Inputs!$H$6:$H$9))),0),"" ) | J12: =IF($A12<=Inputs!$B$13,IF(5<=Inputs!$B$8,IF(Inputs!$B$12>0,MAX(MIN(NORM.INV(RAND(),LOOKUP(T12,Inputs!$J$6:$J$9,Inputs!$G$6:$G$9),LOOKUP(T12,Inputs!$J$6:$J$9,Inputs!$H$6:$H$9)),Inputs!$B$12),-Inputs!$B$12),NORM.INV(RAND(),LOOKUP(T12,Inputs!$J$6:$J$9,Inputs!$G$6:$G$9),LOOKUP(T12,Inputs!$J$6:$J$9,Inputs!$H$6:$H$9))),0),"" ) | K12: =IF($A12<=Inputs!$B$13,IF(6<=Inputs!$B$8,IF(Inputs!$B$12>0,MAX(MIN(NORM.INV(RAND(),LOOKUP(U12,Inputs!$J$6:$J$9,Inputs!$G$6:$G$9),LOOKUP(U12,Inputs!$J$6:$J$9,Inputs!$H$6:$H$9)),Inputs!$B$12),-Inputs!$B$12),NORM.INV(RAND(),LOOKUP(U12,Inputs!$J$6:$J$9,Inputs!$G$6:$G$9),LOOKUP(U12,Inputs!$J$6:$J$9,Inputs!$H$6:$H$9))),0),"" ) | L12: =IF($A12<=Inputs!$B$13,IF(7<=Inputs!$B$8,IF(Inputs!$B$12>0,MAX(MIN(NORM.INV(RAND(),LOOKUP(V12,Inputs!$J$6:$J$9,Inputs!$G$6:$G$9),LOOKUP(V12,Inputs!$J$6:$J$9,Inputs!$H$6:$H$9)),Inputs!$B$12),-Inputs!$B$12),NORM.INV(RAND(),LOOKUP(V12,Inputs!$J$6:$J$9,Inputs!$G$6:$G$9),LOOKUP(V12,Inputs!$J$6:$J$9,Inputs!$H$6:$H$9))),0),"" ) | M12: =IF($A12<=Inputs!$B$13,IF(8<=Inputs!$B$8,IF(Inputs!$B$12>0,MAX(MIN(NORM.INV(RAND(),LOOKUP(W12,Inputs!$J$6:$J$9,Inputs!$G$6:$G$9),LOOKUP(W12,Inputs!$J$6:$J$9,Inputs!$H$6:$H$9)),Inputs!$B$12),-Inputs!$B$12),NORM.INV(RAND(),LOOKUP(W12,Inputs!$J$6:$J$9,Inputs!$G$6:$G$9),LOOKUP(W12,Inputs!$J$6:$J$9,Inputs!$H$6:$H$9))),0),"" ) | N12: =IF($A12<=Inputs!$B$13,IF(9<=Inputs!$B$8,IF(Inputs!$B$12>0,MAX(MIN(NORM.INV(RAND(),LOOKUP(X12,Inputs!$J$6:$J$9,Inputs!$G$6:$G$9),LOOKUP(X12,Inputs!$J$6:$J$9,Inputs!$H$6:$H$9)),Inputs!$B$12),-Inputs!$B$12),NORM.INV(RAND(),LOOKUP(X12,Inputs!$J$6:$J$9,Inputs!$G$6:$G$9),LOOKUP(X12,Inputs!$J$6:$J$9,Inputs!$H$6:$H$9))),0),"" ) | O12: =IF($A12<=Inputs!$B$13,IF(10<=Inputs!$B$8,IF(Inputs!$B$12>0,MAX(MIN(NORM.INV(RAND(),LOOKUP(Y12,Inputs!$J$6:$J$9,Inputs!$G$6:$G$9),LOOKUP(Y12,Inputs!$J$6:$J$9,Inputs!$H$6:$H$9)),Inputs!$B$12),-Inputs!$B$12),NORM.INV(RAND(),LOOKUP(Y12,Inputs!$J$6:$J$9,Inputs!$G$6:$G$9),LOOKUP(Y12,Inputs!$J$6:$J$9,Inputs!$H$6:$H$9))),0),"" ) | P12: =IF($A12<=Inputs!$B$13,RAND(),"") | Q12: =IF($A12<=Inputs!$B$13,RAND(),"") | R12: =IF($A12<=Inputs!$B$13,RAND(),"") | S12: =IF($A12<=Inputs!$B$13,RAND(),"") | T12: =IF($A12<=Inputs!$B$13,RAND(),"") | U12: =IF($A12<=Inputs!$B$13,RAND(),"") | V12: =IF($A12<=Inputs!$B$13,RAND(),"") | W12: =IF($A12<=Inputs!$B$13,RAND(),"") | ... Y12: =IF($A12<=Inputs!$B$13,RAND(),"")
A13: 8 | B13: =IF($A13<=Inputs!$B$13,IF(Inputs!$B$8>0,SUM(F13:O13)/Inputs!$B$8,0),"") | C13: =IF($A13<=Inputs!$B$13,B13/100,"") | D13: =IF($A13<=Inputs!$B$13,C13*Inputs!$B$7,"") | E13: =IF($A13<=Inputs!$B$13,IF(D13>0,1,0),"") | F13: =IF($A13<=Inputs!$B$13,IF(1<=Inputs!$B$8,IF(Inputs!$B$12>0,MAX(MIN(NORM.INV(RAND(),LOOKUP(P13,Inputs!$J$6:$J$9,Inputs!$G$6:$G$9),LOOKUP(P13,Inputs!$J$6:$J$9,Inputs!$H$6:$H$9)),Inputs!$B$12),-Inputs!$B$12),NORM.INV(RAND(),LOOKUP(P13,Inputs!$J$6:$J$9,Inputs!$G$6:$G$9),LOOKUP(P13,Inputs!$J$6:$J$9,Inputs!$H$6:$H$9))),0),"" ) | G13: =IF($A13<=Inputs!$B$13,IF(2<=Inputs!$B$8,IF(Inputs!$B$12>0,MAX(MIN(NORM.INV(RAND(),LOOKUP(Q13,Inputs!$J$6:$J$9,Inputs!$G$6:$G$9),LOOKUP(Q13,Inputs!$J$6:$J$9,Inputs!$H$6:$H$9)),Inputs!$B$12),-Inputs!$B$12),NORM.INV(RAND(),LOOKUP(Q13,Inputs!$J$6:$J$9,Inputs!$G$6:$G$9),LOOKUP(Q13,Inputs!$J$6:$J$9,Inputs!$H$6:$H$9))),0),"" ) | H13: =IF($A13<=Inputs!$B$13,IF(3<=Inputs!$B$8,IF(Inputs!$B$12>0,MAX(MIN(NORM.INV(RAND(),LOOKUP(R13,Inputs!$J$6:$J$9,Inputs!$G$6:$G$9),LOOKUP(R13,Inputs!$J$6:$J$9,Inputs!$H$6:$H$9)),Inputs!$B$12),-Inputs!$B$12),NORM.INV(RAND(),LOOKUP(R13,Inputs!$J$6:$J$9,Inputs!$G$6:$G$9),LOOKUP(R13,Inputs!$J$6:$J$9,Inputs!$H$6:$H$9))),0),"" ) | I13: =IF($A13<=Inputs!$B$13,IF(4<=Inputs!$B$8,IF(Inputs!$B$12>0,MAX(MIN(NORM.INV(RAND(),LOOKUP(S13,Inputs!$J$6:$J$9,Inputs!$G$6:$G$9),LOOKUP(S13,Inputs!$J$6:$J$9,Inputs!$H$6:$H$9)),Inputs!$B$12),-Inputs!$B$12),NORM.INV(RAND(),LOOKUP(S13,Inputs!$J$6:$J$9,Inputs!$G$6:$G$9),LOOKUP(S13,Inputs!$J$6:$J$9,Inputs!$H$6:$H$9))),0),"" ) | J13: =IF($A13<=Inputs!$B$13,IF(5<=Inputs!$B$8,IF(Inputs!$B$12>0,MAX(MIN(NORM.INV(RAND(),LOOKUP(T13,Inputs!$J$6:$J$9,Inputs!$G$6:$G$9),LOOKUP(T13,Inputs!$J$6:$J$9,Inputs!$H$6:$H$9)),Inputs!$B$12),-Inputs!$B$12),NORM.INV(RAND(),LOOKUP(T13,Inputs!$J$6:$J$9,Inputs!$G$6:$G$9),LOOKUP(T13,Inputs!$J$6:$J$9,Inputs!$H$6:$H$9))),0),"" ) | K13: =IF($A13<=Inputs!$B$13,IF(6<=Inputs!$B$8,IF(Inputs!$B$12>0,MAX(MIN(NORM.INV(RAND(),LOOKUP(U13,Inputs!$J$6:$J$9,Inputs!$G$6:$G$9),LOOKUP(U13,Inputs!$J$6:$J$9,Inputs!$H$6:$H$9)),Inputs!$B$12),-Inputs!$B$12),NORM.INV(RAND(),LOOKUP(U13,Inputs!$J$6:$J$9,Inputs!$G$6:$G$9),LOOKUP(U13,Inputs!$J$6:$J$9,Inputs!$H$6:$H$9))),0),"" ) | L13: =IF($A13<=Inputs!$B$13,IF(7<=Inputs!$B$8,IF(Inputs!$B$12>0,MAX(MIN(NORM.INV(RAND(),LOOKUP(V13,Inputs!$J$6:$J$9,Inputs!$G$6:$G$9),LOOKUP(V13,Inputs!$J$6:$J$9,Inputs!$H$6:$H$9)),Inputs!$B$12),-Inputs!$B$12),NORM.INV(RAND(),LOOKUP(V13,Inputs!$J$6:$J$9,Inputs!$G$6:$G$9),LOOKUP(V13,Inputs!$J$6:$J$9,Inputs!$H$6:$H$9))),0),"" ) | M13: =COUNTIFS($B$6:$B$5005,">="&K13,$B$6:$B$5005,"<"&L13) | N13: =IF($A13<=Inputs!$B$13,IF(9<=Inputs!$B$8,IF(Inputs!$B$12>0,MAX(MIN(NORM.INV(RAND(),LOOKUP(X13,Inputs!$J$6:$J$9,Inputs!$G$6:$G$9),LOOKUP(X13,Inputs!$J$6:$J$9,Inputs!$H$6:$H$9)),Inputs!$B$12),-Inputs!$B$12),NORM.INV(RAND(),LOOKUP(X13,Inputs!$J$6:$J$9,Inputs!$G$6:$G$9),LOOKUP(X13,Inputs!$J$6:$J$9,Inputs!$H$6:$H$9))),0),"" ) | O13: =IF($A13<=Inputs!$B$13,IF(10<=Inputs!$B$8,IF(Inputs!$B$12>0,MAX(MIN(NORM.INV(RAND(),LOOKUP(Y13,Inputs!$J$6:$J$9,Inputs!$G$6:$G$9),LOOKUP(Y13,Inputs!$J$6:$J$9,Inputs!$H$6:$H$9)),Inputs!$B$12),-Inputs!$B$12),NORM.INV(RAND(),LOOKUP(Y13,Inputs!$J$6:$J$9,Inputs!$G$6:$G$9),LOOKUP(Y13,Inputs!$J$6:$J$9,Inputs!$H$6:$H$9))),0),"" ) | P13: =IF($A13<=Inputs!$B$13,RAND(),"") | Q13: =IF($A13<=Inputs!$B$13,RAND(),"") | R13: =IF($A13<=Inputs!$B$13,RAND(),"") | S13: =IF($A13<=Inputs!$B$13,RAND(),"") | T13: =IF($A13<=Inputs!$B$13,RAND(),"") | U13: =IF($A13<=Inputs!$B$13,RAND(),"") | V13: =IF($A13<=Inputs!$B$13,RAND(),"") | W13: =IF($A13<=Inputs!$B$13,RAND(),"") | ... Y13: =IF($A13<=Inputs!$B$13,RAND(),"")
A14: 9 | B14: =IF($A14<=Inputs!$B$13,IF(Inputs!$B$8>0,SUM(F14:O14)/Inputs!$B$8,0),"") | C14: =IF($A14<=Inputs!$B$13,B14/100,"") | D14: =IF($A14<=Inputs!$B$13,C14*Inputs!$B$7,"") | E14: =IF($A14<=Inputs!$B$13,IF(D14>0,1,0),"") | F14: =IF($A14<=Inputs!$B$13,IF(1<=Inputs!$B$8,IF(Inputs!$B$12>0,MAX(MIN(NORM.INV(RAND(),LOOKUP(P14,Inputs!$J$6:$J$9,Inputs!$G$6:$G$9),LOOKUP(P14,Inputs!$J$6:$J$9,Inputs!$H$6:$H$9)),Inputs!$B$12),-Inputs!$B$12),NORM.INV(RAND(),LOOKUP(P14,Inputs!$J$6:$J$9,Inputs!$G$6:$G$9),LOOKUP(P14,Inputs!$J$6:$J$9,Inputs!$H$6:$H$9))),0),"" ) | G14: =IF($A14<=Inputs!$B$13,IF(2<=Inputs!$B$8,IF(Inputs!$B$12>0,MAX(MIN(NORM.INV(RAND(),LOOKUP(Q14,Inputs!$J$6:$J$9,Inputs!$G$6:$G$9),LOOKUP(Q14,Inputs!$J$6:$J$9,Inputs!$H$6:$H$9)),Inputs!$B$12),-Inputs!$B$12),NORM.INV(RAND(),LOOKUP(Q14,Inputs!$J$6:$J$9,Inputs!$G$6:$G$9),LOOKUP(Q14,Inputs!$J$6:$J$9,Inputs!$H$6:$H$9))),0),"" ) | H14: =IF($A14<=Inputs!$B$13,IF(3<=Inputs!$B$8,IF(Inputs!$B$12>0,MAX(MIN(NORM.INV(RAND(),LOOKUP(R14,Inputs!$J$6:$J$9,Inputs!$G$6:$G$9),LOOKUP(R14,Inputs!$J$6:$J$9,Inputs!$H$6:$H$9)),Inputs!$B$12),-Inputs!$B$12),NORM.INV(RAND(),LOOKUP(R14,Inputs!$J$6:$J$9,Inputs!$G$6:$G$9),LOOKUP(R14,Inputs!$J$6:$J$9,Inputs!$H$6:$H$9))),0),"" ) | I14: =IF($A14<=Inputs!$B$13,IF(4<=Inputs!$B$8,IF(Inputs!$B$12>0,MAX(MIN(NORM.INV(RAND(),LOOKUP(S14,Inputs!$J$6:$J$9,Inputs!$G$6:$G$9),LOOKUP(S14,Inputs!$J$6:$J$9,Inputs!$H$6:$H$9)),Inputs!$B$12),-Inputs!$B$12),NORM.INV(RAND(),LOOKUP(S14,Inputs!$J$6:$J$9,Inputs!$G$6:$G$9),LOOKUP(S14,Inputs!$J$6:$J$9,Inputs!$H$6:$H$9))),0),"" ) | J14: =IF($A14<=Inputs!$B$13,IF(5<=Inputs!$B$8,IF(Inputs!$B$12>0,MAX(MIN(NORM.INV(RAND(),LOOKUP(T14,Inputs!$J$6:$J$9,Inputs!$G$6:$G$9),LOOKUP(T14,Inputs!$J$6:$J$9,Inputs!$H$6:$H$9)),Inputs!$B$12),-Inputs!$B$12),NORM.INV(RAND(),LOOKUP(T14,Inputs!$J$6:$J$9,Inputs!$G$6:$G$9),LOOKUP(T14,Inputs!$J$6:$J$9,Inputs!$H$6:$H$9))),0),"" ) | K14: =IF($A14<=Inputs!$B$13,IF(6<=Inputs!$B$8,IF(Inputs!$B$12>0,MAX(MIN(NORM.INV(RAND(),LOOKUP(U14,Inputs!$J$6:$J$9,Inputs!$G$6:$G$9),LOOKUP(U14,Inputs!$J$6:$J$9,Inputs!$H$6:$H$9)),Inputs!$B$12),-Inputs!$B$12),NORM.INV(RAND(),LOOKUP(U14,Inputs!$J$6:$J$9,Inputs!$G$6:$G$9),LOOKUP(U14,Inputs!$J$6:$J$9,Inputs!$H$6:$H$9))),0),"" ) | L14: =IF($A14<=Inputs!$B$13,IF(7<=Inputs!$B$8,IF(Inputs!$B$12>0,MAX(MIN(NORM.INV(RAND(),LOOKUP(V14,Inputs!$J$6:$J$9,Inputs!$G$6:$G$9),LOOKUP(V14,Inputs!$J$6:$J$9,Inputs!$H$6:$H$9)),Inputs!$B$12),-Inputs!$B$12),NORM.INV(RAND(),LOOKUP(V14,Inputs!$J$6:$J$9,Inputs!$G$6:$G$9),LOOKUP(V14,Inputs!$J$6:$J$9,Inputs!$H$6:$H$9))),0),"" ) | M14: =COUNTIFS($B$6:$B$5005,">="&K14,$B$6:$B$5005,"<"&L14) | N14: =IF($A14<=Inputs!$B$13,IF(9<=Inputs!$B$8,IF(Inputs!$B$12>0,MAX(MIN(NORM.INV(RAND(),LOOKUP(X14,Inputs!$J$6:$J$9,Inputs!$G$6:$G$9),LOOKUP(X14,Inputs!$J$6:$J$9,Inputs!$H$6:$H$9)),Inputs!$B$12),-Inputs!$B$12),NORM.INV(RAND(),LOOKUP(X14,Inputs!$J$6:$J$9,Inputs!$G$6:$G$9),LOOKUP(X14,Inputs!$J$6:$J$9,Inputs!$H$6:$H$9))),0),"" ) | O14: =IF($A14<=Inputs!$B$13,IF(10<=Inputs!$B$8,IF(Inputs!$B$12>0,MAX(MIN(NORM.INV(RAND(),LOOKUP(Y14,Inputs!$J$6:$J$9,Inputs!$G$6:$G$9),LOOKUP(Y14,Inputs!$J$6:$J$9,Inputs!$H$6:$H$9)),Inputs!$B$12),-Inputs!$B$12),NORM.INV(RAND(),LOOKUP(Y14,Inputs!$J$6:$J$9,Inputs!$G$6:$G$9),LOOKUP(Y14,Inputs!$J$6:$J$9,Inputs!$H$6:$H$9))),0),"" ) | P14: =IF($A14<=Inputs!$B$13,RAND(),"") | Q14: =IF($A14<=Inputs!$B$13,RAND(),"") | R14: =IF($A14<=Inputs!$B$13,RAND(),"") | S14: =IF($A14<=Inputs!$B$13,RAND(),"") | T14: =IF($A14<=Inputs!$B$13,RAND(),"") | U14: =IF($A14<=Inputs!$B$13,RAND(),"") | V14: =IF($A14<=Inputs!$B$13,RAND(),"") | W14: =IF($A14<=Inputs!$B$13,RAND(),"") | ... Y14: =IF($A14<=Inputs!$B$13,RAND(),"")
A15: 10 | B15: =IF($A15<=Inputs!$B$13,IF(Inputs!$B$8>0,SUM(F15:O15)/Inputs!$B$8,0),"") | C15: =IF($A15<=Inputs!$B$13,B15/100,"") | D15: =IF($A15<=Inputs!$B$13,C15*Inputs!$B$7,"") | E15: =IF($A15<=Inputs!$B$13,IF(D15>0,1,0),"") | F15: =IF($A15<=Inputs!$B$13,IF(1<=Inputs!$B$8,IF(Inputs!$B$12>0,MAX(MIN(NORM.INV(RAND(),LOOKUP(P15,Inputs!$J$6:$J$9,Inputs!$G$6:$G$9),LOOKUP(P15,Inputs!$J$6:$J$9,Inputs!$H$6:$H$9)),Inputs!$B$12),-Inputs!$B$12),NORM.INV(RAND(),LOOKUP(P15,Inputs!$J$6:$J$9,Inputs!$G$6:$G$9),LOOKUP(P15,Inputs!$J$6:$J$9,Inputs!$H$6:$H$9))),0),"" ) | G15: =IF($A15<=Inputs!$B$13,IF(2<=Inputs!$B$8,IF(Inputs!$B$12>0,MAX(MIN(NORM.INV(RAND(),LOOKUP(Q15,Inputs!$J$6:$J$9,Inputs!$G$6:$G$9),LOOKUP(Q15,Inputs!$J$6:$J$9,Inputs!$H$6:$H$9)),Inputs!$B$12),-Inputs!$B$12),NORM.INV(RAND(),LOOKUP(Q15,Inputs!$J$6:$J$9,Inputs!$G$6:$G$9),LOOKUP(Q15,Inputs!$J$6:$J$9,Inputs!$H$6:$H$9))),0),"" ) | H15: =IF($A15<=Inputs!$B$13,IF(3<=Inputs!$B$8,IF(Inputs!$B$12>0,MAX(MIN(NORM.INV(RAND(),LOOKUP(R15,Inputs!$J$6:$J$9,Inputs!$G$6:$G$9),LOOKUP(R15,Inputs!$J$6:$J$9,Inputs!$H$6:$H$9)),Inputs!$B$12),-Inputs!$B$12),NORM.INV(RAND(),LOOKUP(R15,Inputs!$J$6:$J$9,Inputs!$G$6:$G$9),LOOKUP(R15,Inputs!$J$6:$J$9,Inputs!$H$6:$H$9))),0),"" ) | I15: =IF($A15<=Inputs!$B$13,IF(4<=Inputs!$B$8,IF(Inputs!$B$12>0,MAX(MIN(NORM.INV(RAND(),LOOKUP(S15,Inputs!$J$6:$J$9,Inputs!$G$6:$G$9),LOOKUP(S15,Inputs!$J$6:$J$9,Inputs!$H$6:$H$9)),Inputs!$B$12),-Inputs!$B$12),NORM.INV(RAND(),LOOKUP(S15,Inputs!$J$6:$J$9,Inputs!$G$6:$G$9),LOOKUP(S15,Inputs!$J$6:$J$9,Inputs!$H$6:$H$9))),0),"" ) | J15: =IF($A15<=Inputs!$B$13,IF(5<=Inputs!$B$8,IF(Inputs!$B$12>0,MAX(MIN(NORM.INV(RAND(),LOOKUP(T15,Inputs!$J$6:$J$9,Inputs!$G$6:$G$9),LOOKUP(T15,Inputs!$J$6:$J$9,Inputs!$H$6:$H$9)),Inputs!$B$12),-Inputs!$B$12),NORM.INV(RAND(),LOOKUP(T15,Inputs!$J$6:$J$9,Inputs!$G$6:$G$9),LOOKUP(T15,Inputs!$J$6:$J$9,Inputs!$H$6:$H$9))),0),"" ) | K15: =IF($A15<=Inputs!$B$13,IF(6<=Inputs!$B$8,IF(Inputs!$B$12>0,MAX(MIN(NORM.INV(RAND(),LOOKUP(U15,Inputs!$J$6:$J$9,Inputs!$G$6:$G$9),LOOKUP(U15,Inputs!$J$6:$J$9,Inputs!$H$6:$H$9)),Inputs!$B$12),-Inputs!$B$12),NORM.INV(RAND(),LOOKUP(U15,Inputs!$J$6:$J$9,Inputs!$G$6:$G$9),LOOKUP(U15,Inputs!$J$6:$J$9,Inputs!$H$6:$H$9))),0),"" ) | L15: =IF($A15<=Inputs!$B$13,IF(7<=Inputs!$B$8,IF(Inputs!$B$12>0,MAX(MIN(NORM.INV(RAND(),LOOKUP(V15,Inputs!$J$6:$J$9,Inputs!$G$6:$G$9),LOOKUP(V15,Inputs!$J$6:$J$9,Inputs!$H$6:$H$9)),Inputs!$B$12),-Inputs!$B$12),NORM.INV(RAND(),LOOKUP(V15,Inputs!$J$6:$J$9,Inputs!$G$6:$G$9),LOOKUP(V15,Inputs!$J$6:$J$9,Inputs!$H$6:$H$9))),0),"" ) | M15: =COUNTIFS($B$6:$B$5005,">="&K15,$B$6:$B$5005,"<"&L15) | N15: =IF($A15<=Inputs!$B$13,IF(9<=Inputs!$B$8,IF(Inputs!$B$12>0,MAX(MIN(NORM.INV(RAND(),LOOKUP(X15,Inputs!$J$6:$J$9,Inputs!$G$6:$G$9),LOOKUP(X15,Inputs!$J$6:$J$9,Inputs!$H$6:$H$9)),Inputs!$B$12),-Inputs!$B$12),NORM.INV(RAND(),LOOKUP(X15,Inputs!$J$6:$J$9,Inputs!$G$6:$G$9),LOOKUP(X15,Inputs!$J$6:$J$9,Inputs!$H$6:$H$9))),0),"" ) | O15: =IF($A15<=Inputs!$B$13,IF(10<=Inputs!$B$8,IF(Inputs!$B$12>0,MAX(MIN(NORM.INV(RAND(),LOOKUP(Y15,Inputs!$J$6:$J$9,Inputs!$G$6:$G$9),LOOKUP(Y15,Inputs!$J$6:$J$9,Inputs!$H$6:$H$9)),Inputs!$B$12),-Inputs!$B$12),NORM.INV(RAND(),LOOKUP(Y15,Inputs!$J$6:$J$9,Inputs!$G$6:$G$9),LOOKUP(Y15,Inputs!$J$6:$J$9,Inputs!$H$6:$H$9))),0),"" ) | P15: =IF($A15<=Inputs!$B$13,RAND(),"") | Q15: =IF($A15<=Inputs!$B$13,RAND(),"") | R15: =IF($A15<=Inputs!$B$13,RAND(),"") | S15: =IF($A15<=Inputs!$B$13,RAND(),"") | T15: =IF($A15<=Inputs!$B$13,RAND(),"") | U15: =IF($A15<=Inputs!$B$13,RAND(),"") | V15: =IF($A15<=Inputs!$B$13,RAND(),"") | W15: =IF($A15<=Inputs!$B$13,RAND(),"") | ... Y15: =IF($A15<=Inputs!$B$13,RAND(),"")
A16: 11 | B16: =IF($A16<=Inputs!$B$13,IF(Inputs!$B$8>0,SUM(F16:O16)/Inputs!$B$8,0),"") | C16: =IF($A16<=Inputs!$B$13,B16/100,"") | D16: =IF($A16<=Inputs!$B$13,C16*Inputs!$B$7,"") | E16: =IF($A16<=Inputs!$B$13,IF(D16>0,1,0),"") | F16: =IF($A16<=Inputs!$B$13,IF(1<=Inputs!$B$8,IF(Inputs!$B$12>0,MAX(MIN(NORM.INV(RAND(),LOOKUP(P16,Inputs!$J$6:$J$9,Inputs!$G$6:$G$9),LOOKUP(P16,Inputs!$J$6:$J$9,Inputs!$H$6:$H$9)),Inputs!$B$12),-Inputs!$B$12),NORM.INV(RAND(),LOOKUP(P16,Inputs!$J$6:$J$9,Inputs!$G$6:$G$9),LOOKUP(P16,Inputs!$J$6:$J$9,Inputs!$H$6:$H$9))),0),"" ) | G16: =IF($A16<=Inputs!$B$13,IF(2<=Inputs!$B$8,IF(Inputs!$B$12>0,MAX(MIN(NORM.INV(RAND(),LOOKUP(Q16,Inputs!$J$6:$J$9,Inputs!$G$6:$G$9),LOOKUP(Q16,Inputs!$J$6:$J$9,Inputs!$H$6:$H$9)),Inputs!$B$12),-Inputs!$B$12),NORM.INV(RAND(),LOOKUP(Q16,Inputs!$J$6:$J$9,Inputs!$G$6:$G$9),LOOKUP(Q16,Inputs!$J$6:$J$9,Inputs!$H$6:$H$9))),0),"" ) | H16: =IF($A16<=Inputs!$B$13,IF(3<=Inputs!$B$8,IF(Inputs!$B$12>0,MAX(MIN(NORM.INV(RAND(),LOOKUP(R16,Inputs!$J$6:$J$9,Inputs!$G$6:$G$9),LOOKUP(R16,Inputs!$J$6:$J$9,Inputs!$H$6:$H$9)),Inputs!$B$12),-Inputs!$B$12),NORM.INV(RAND(),LOOKUP(R16,Inputs!$J$6:$J$9,Inputs!$G$6:$G$9),LOOKUP(R16,Inputs!$J$6:$J$9,Inputs!$H$6:$H$9))),0),"" ) | I16: =IF($A16<=Inputs!$B$13,IF(4<=Inputs!$B$8,IF(Inputs!$B$12>0,MAX(MIN(NORM.INV(RAND(),LOOKUP(S16,Inputs!$J$6:$J$9,Inputs!$G$6:$G$9),LOOKUP(S16,Inputs!$J$6:$J$9,Inputs!$H$6:$H$9)),Inputs!$B$12),-Inputs!$B$12),NORM.INV(RAND(),LOOKUP(S16,Inputs!$J$6:$J$9,Inputs!$G$6:$G$9),LOOKUP(S16,Inputs!$J$6:$J$9,Inputs!$H$6:$H$9))),0),"" ) | J16: =IF($A16<=Inputs!$B$13,IF(5<=Inputs!$B$8,IF(Inputs!$B$12>0,MAX(MIN(NORM.INV(RAND(),LOOKUP(T16,Inputs!$J$6:$J$9,Inputs!$G$6:$G$9),LOOKUP(T16,Inputs!$J$6:$J$9,Inputs!$H$6:$H$9)),Inputs!$B$12),-Inputs!$B$12),NORM.INV(RAND(),LOOKUP(T16,Inputs!$J$6:$J$9,Inputs!$G$6:$G$9),LOOKUP(T16,Inputs!$J$6:$J$9,Inputs!$H$6:$H$9))),0),"" ) | K16: =IF($A16<=Inputs!$B$13,IF(6<=Inputs!$B$8,IF(Inputs!$B$12>0,MAX(MIN(NORM.INV(RAND(),LOOKUP(U16,Inputs!$J$6:$J$9,Inputs!$G$6:$G$9),LOOKUP(U16,Inputs!$J$6:$J$9,Inputs!$H$6:$H$9)),Inputs!$B$12),-Inputs!$B$12),NORM.INV(RAND(),LOOKUP(U16,Inputs!$J$6:$J$9,Inputs!$G$6:$G$9),LOOKUP(U16,Inputs!$J$6:$J$9,Inputs!$H$6:$H$9))),0),"" ) | L16: =IF($A16<=Inputs!$B$13,IF(7<=Inputs!$B$8,IF(Inputs!$B$12>0,MAX(MIN(NORM.INV(RAND(),LOOKUP(V16,Inputs!$J$6:$J$9,Inputs!$G$6:$G$9),LOOKUP(V16,Inputs!$J$6:$J$9,Inputs!$H$6:$H$9)),Inputs!$B$12),-Inputs!$B$12),NORM.INV(RAND(),LOOKUP(V16,Inputs!$J$6:$J$9,Inputs!$G$6:$G$9),LOOKUP(V16,Inputs!$J$6:$J$9,Inputs!$H$6:$H$9))),0),"" ) | M16: =COUNTIFS($B$6:$B$5005,">="&K16,$B$6:$B$5005,"<"&L16) | N16: =IF($A16<=Inputs!$B$13,IF(9<=Inputs!$B$8,IF(Inputs!$B$12>0,MAX(MIN(NORM.INV(RAND(),LOOKUP(X16,Inputs!$J$6:$J$9,Inputs!$G$6:$G$9),LOOKUP(X16,Inputs!$J$6:$J$9,Inputs!$H$6:$H$9)),Inputs!$B$12),-Inputs!$B$12),NORM.INV(RAND(),LOOKUP(X16,Inputs!$J$6:$J$9,Inputs!$G$6:$G$9),LOOKUP(X16,Inputs!$J$6:$J$9,Inputs!$H$6:$H$9))),0),"" ) | O16: =IF($A16<=Inputs!$B$13,IF(10<=Inputs!$B$8,IF(Inputs!$B$12>0,MAX(MIN(NORM.INV(RAND(),LOOKUP(Y16,Inputs!$J$6:$J$9,Inputs!$G$6:$G$9),LOOKUP(Y16,Inputs!$J$6:$J$9,Inputs!$H$6:$H$9)),Inputs!$B$12),-Inputs!$B$12),NORM.INV(RAND(),LOOKUP(Y16,Inputs!$J$6:$J$9,Inputs!$G$6:$G$9),LOOKUP(Y16,Inputs!$J$6:$J$9,Inputs!$H$6:$H$9))),0),"" ) | P16: =IF($A16<=Inputs!$B$13,RAND(),"") | Q16: =IF($A16<=Inputs!$B$13,RAND(),"") | R16: =IF($A16<=Inputs!$B$13,RAND(),"") | S16: =IF($A16<=Inputs!$B$13,RAND(),"") | T16: =IF($A16<=Inputs!$B$13,RAND(),"") | U16: =IF($A16<=Inputs!$B$13,RAND(),"") | V16: =IF($A16<=Inputs!$B$13,RAND(),"") | W16: =IF($A16<=Inputs!$B$13,RAND(),"") | ... Y16: =IF($A16<=Inputs!$B$13,RAND(),"")
A17: 12 | B17: =IF($A17<=Inputs!$B$13,IF(Inputs!$B$8>0,SUM(F17:O17)/Inputs!$B$8,0),"") | C17: =IF($A17<=Inputs!$B$13,B17/100,"") | D17: =IF($A17<=Inputs!$B$13,C17*Inputs!$B$7,"") | E17: =IF($A17<=Inputs!$B$13,IF(D17>0,1,0),"") | F17: =IF($A17<=Inputs!$B$13,IF(1<=Inputs!$B$8,IF(Inputs!$B$12>0,MAX(MIN(NORM.INV(RAND(),LOOKUP(P17,Inputs!$J$6:$J$9,Inputs!$G$6:$G$9),LOOKUP(P17,Inputs!$J$6:$J$9,Inputs!$H$6:$H$9)),Inputs!$B$12),-Inputs!$B$12),NORM.INV(RAND(),LOOKUP(P17,Inputs!$J$6:$J$9,Inputs!$G$6:$G$9),LOOKUP(P17,Inputs!$J$6:$J$9,Inputs!$H$6:$H$9))),0),"" ) | G17: =IF($A17<=Inputs!$B$13,IF(2<=Inputs!$B$8,IF(Inputs!$B$12>0,MAX(MIN(NORM.INV(RAND(),LOOKUP(Q17,Inputs!$J$6:$J$9,Inputs!$G$6:$G$9),LOOKUP(Q17,Inputs!$J$6:$J$9,Inputs!$H$6:$H$9)),Inputs!$B$12),-Inputs!$B$12),NORM.INV(RAND(),LOOKUP(Q17,Inputs!$J$6:$J$9,Inputs!$G$6:$G$9),LOOKUP(Q17,Inputs!$J$6:$J$9,Inputs!$H$6:$H$9))),0),"" ) | H17: =IF($A17<=Inputs!$B$13,IF(3<=Inputs!$B$8,IF(Inputs!$B$12>0,MAX(MIN(NORM.INV(RAND(),LOOKUP(R17,Inputs!$J$6:$J$9,Inputs!$G$6:$G$9),LOOKUP(R17,Inputs!$J$6:$J$9,Inputs!$H$6:$H$9)),Inputs!$B$12),-Inputs!$B$12),NORM.INV(RAND(),LOOKUP(R17,Inputs!$J$6:$J$9,Inputs!$G$6:$G$9),LOOKUP(R17,Inputs!$J$6:$J$9,Inputs!$H$6:$H$9))),0),"" ) | I17: =IF($A17<=Inputs!$B$13,IF(4<=Inputs!$B$8,IF(Inputs!$B$12>0,MAX(MIN(NORM.INV(RAND(),LOOKUP(S17,Inputs!$J$6:$J$9,Inputs!$G$6:$G$9),LOOKUP(S17,Inputs!$J$6:$J$9,Inputs!$H$6:$H$9)),Inputs!$B$12),-Inputs!$B$12),NORM.INV(RAND(),LOOKUP(S17,Inputs!$J$6:$J$9,Inputs!$G$6:$G$9),LOOKUP(S17,Inputs!$J$6:$J$9,Inputs!$H$6:$H$9))),0),"" ) | J17: =IF($A17<=Inputs!$B$13,IF(5<=Inputs!$B$8,IF(Inputs!$B$12>0,MAX(MIN(NORM.INV(RAND(),LOOKUP(T17,Inputs!$J$6:$J$9,Inputs!$G$6:$G$9),LOOKUP(T17,Inputs!$J$6:$J$9,Inputs!$H$6:$H$9)),Inputs!$B$12),-Inputs!$B$12),NORM.INV(RAND(),LOOKUP(T17,Inputs!$J$6:$J$9,Inputs!$G$6:$G$9),LOOKUP(T17,Inputs!$J$6:$J$9,Inputs!$H$6:$H$9))),0),"" ) | K17: =IF($A17<=Inputs!$B$13,IF(6<=Inputs!$B$8,IF(Inputs!$B$12>0,MAX(MIN(NORM.INV(RAND(),LOOKUP(U17,Inputs!$J$6:$J$9,Inputs!$G$6:$G$9),LOOKUP(U17,Inputs!$J$6:$J$9,Inputs!$H$6:$H$9)),Inputs!$B$12),-Inputs!$B$12),NORM.INV(RAND(),LOOKUP(U17,Inputs!$J$6:$J$9,Inputs!$G$6:$G$9),LOOKUP(U17,Inputs!$J$6:$J$9,Inputs!$H$6:$H$9))),0),"" ) | L17: =IF($A17<=Inputs!$B$13,IF(7<=Inputs!$B$8,IF(Inputs!$B$12>0,MAX(MIN(NORM.INV(RAND(),LOOKUP(V17,Inputs!$J$6:$J$9,Inputs!$G$6:$G$9),LOOKUP(V17,Inputs!$J$6:$J$9,Inputs!$H$6:$H$9)),Inputs!$B$12),-Inputs!$B$12),NORM.INV(RAND(),LOOKUP(V17,Inputs!$J$6:$J$9,Inputs!$G$6:$G$9),LOOKUP(V17,Inputs!$J$6:$J$9,Inputs!$H$6:$H$9))),0),"" ) | M17: =COUNTIFS($B$6:$B$5005,">="&K17,$B$6:$B$5005,"<"&L17) | N17: =IF($A17<=Inputs!$B$13,IF(9<=Inputs!$B$8,IF(Inputs!$B$12>0,MAX(MIN(NORM.INV(RAND(),LOOKUP(X17,Inputs!$J$6:$J$9,Inputs!$G$6:$G$9),LOOKUP(X17,Inputs!$J$6:$J$9,Inputs!$H$6:$H$9)),Inputs!$B$12),-Inputs!$B$12),NORM.INV(RAND(),LOOKUP(X17,Inputs!$J$6:$J$9,Inputs!$G$6:$G$9),LOOKUP(X17,Inputs!$J$6:$J$9,Inputs!$H$6:$H$9))),0),"" ) | O17: =IF($A17<=Inputs!$B$13,IF(10<=Inputs!$B$8,IF(Inputs!$B$12>0,MAX(MIN(NORM.INV(RAND(),LOOKUP(Y17,Inputs!$J$6:$J$9,Inputs!$G$6:$G$9),LOOKUP(Y17,Inputs!$J$6:$J$9,Inputs!$H$6:$H$9)),Inputs!$B$12),-Inputs!$B$12),NORM.INV(RAND(),LOOKUP(Y17,Inputs!$J$6:$J$9,Inputs!$G$6:$G$9),LOOKUP(Y17,Inputs!$J$6:$J$9,Inputs!$H$6:$H$9))),0),"" ) | P17: =IF($A17<=Inputs!$B$13,RAND(),"") | Q17: =IF($A17<=Inputs!$B$13,RAND(),"") | R17: =IF($A17<=Inputs!$B$13,RAND(),"") | S17: =IF($A17<=Inputs!$B$13,RAND(),"") | T17: =IF($A17<=Inputs!$B$13,RAND(),"") | U17: =IF($A17<=Inputs!$B$13,RAND(),"") | V17: =IF($A17<=Inputs!$B$13,RAND(),"") | W17: =IF($A17<=Inputs!$B$13,RAND(),"") | ... Y17: =IF($A17<=Inputs!$B$13,RAND(),"")
A18: 13 | B18: =IF($A18<=Inputs!$B$13,IF(Inputs!$B$8>0,SUM(F18:O18)/Inputs!$B$8,0),"") | C18: =IF($A18<=Inputs!$B$13,B18/100,"") | D18: =IF($A18<=Inputs!$B$13,C18*Inputs!$B$7,"") | E18: =IF($A18<=Inputs!$B$13,IF(D18>0,1,0),"") | F18: =IF($A18<=Inputs!$B$13,IF(1<=Inputs!$B$8,IF(Inputs!$B$12>0,MAX(MIN(NORM.INV(RAND(),LOOKUP(P18,Inputs!$J$6:$J$9,Inputs!$G$6:$G$9),LOOKUP(P18,Inputs!$J$6:$J$9,Inputs!$H$6:$H$9)),Inputs!$B$12),-Inputs!$B$12),NORM.INV(RAND(),LOOKUP(P18,Inputs!$J$6:$J$9,Inputs!$G$6:$G$9),LOOKUP(P18,Inputs!$J$6:$J$9,Inputs!$H$6:$H$9))),0),"" ) | G18: =IF($A18<=Inputs!$B$13,IF(2<=Inputs!$B$8,IF(Inputs!$B$12>0,MAX(MIN(NORM.INV(RAND(),LOOKUP(Q18,Inputs!$J$6:$J$9,Inputs!$G$6:$G$9),LOOKUP(Q18,Inputs!$J$6:$J$9,Inputs!$H$6:$H$9)),Inputs!$B$12),-Inputs!$B$12),NORM.INV(RAND(),LOOKUP(Q18,Inputs!$J$6:$J$9,Inputs!$G$6:$G$9),LOOKUP(Q18,Inputs!$J$6:$J$9,Inputs!$H$6:$H$9))),0),"" ) | H18: =IF($A18<=Inputs!$B$13,IF(3<=Inputs!$B$8,IF(Inputs!$B$12>0,MAX(MIN(NORM.INV(RAND(),LOOKUP(R18,Inputs!$J$6:$J$9,Inputs!$G$6:$G$9),LOOKUP(R18,Inputs!$J$6:$J$9,Inputs!$H$6:$H$9)),Inputs!$B$12),-Inputs!$B$12),NORM.INV(RAND(),LOOKUP(R18,Inputs!$J$6:$J$9,Inputs!$G$6:$G$9),LOOKUP(R18,Inputs!$J$6:$J$9,Inputs!$H$6:$H$9))),0),"" ) | I18: =IF($A18<=Inputs!$B$13,IF(4<=Inputs!$B$8,IF(Inputs!$B$12>0,MAX(MIN(NORM.INV(RAND(),LOOKUP(S18,Inputs!$J$6:$J$9,Inputs!$G$6:$G$9),LOOKUP(S18,Inputs!$J$6:$J$9,Inputs!$H$6:$H$9)),Inputs!$B$12),-Inputs!$B$12),NORM.INV(RAND(),LOOKUP(S18,Inputs!$J$6:$J$9,Inputs!$G$6:$G$9),LOOKUP(S18,Inputs!$J$6:$J$9,Inputs!$H$6:$H$9))),0),"" ) | J18: =IF($A18<=Inputs!$B$13,IF(5<=Inputs!$B$8,IF(Inputs!$B$12>0,MAX(MIN(NORM.INV(RAND(),LOOKUP(T18,Inputs!$J$6:$J$9,Inputs!$G$6:$G$9),LOOKUP(T18,Inputs!$J$6:$J$9,Inputs!$H$6:$H$9)),Inputs!$B$12),-Inputs!$B$12),NORM.INV(RAND(),LOOKUP(T18,Inputs!$J$6:$J$9,Inputs!$G$6:$G$9),LOOKUP(T18,Inputs!$J$6:$J$9,Inputs!$H$6:$H$9))),0),"" ) | K18: =IF($A18<=Inputs!$B$13,IF(6<=Inputs!$B$8,IF(Inputs!$B$12>0,MAX(MIN(NORM.INV(RAND(),LOOKUP(U18,Inputs!$J$6:$J$9,Inputs!$G$6:$G$9),LOOKUP(U18,Inputs!$J$6:$J$9,Inputs!$H$6:$H$9)),Inputs!$B$12),-Inputs!$B$12),NORM.INV(RAND(),LOOKUP(U18,Inputs!$J$6:$J$9,Inputs!$G$6:$G$9),LOOKUP(U18,Inputs!$J$6:$J$9,Inputs!$H$6:$H$9))),0),"" ) | L18: =IF($A18<=Inputs!$B$13,IF(7<=Inputs!$B$8,IF(Inputs!$B$12>0,MAX(MIN(NORM.INV(RAND(),LOOKUP(V18,Inputs!$J$6:$J$9,Inputs!$G$6:$G$9),LOOKUP(V18,Inputs!$J$6:$J$9,Inputs!$H$6:$H$9)),Inputs!$B$12),-Inputs!$B$12),NORM.INV(RAND(),LOOKUP(V18,Inputs!$J$6:$J$9,Inputs!$G$6:$G$9),LOOKUP(V18,Inputs!$J$6:$J$9,Inputs!$H$6:$H$9))),0),"" ) | M18: =COUNTIFS($B$6:$B$5005,">="&K18,$B$6:$B$5005,"<"&L18) | N18: =IF($A18<=Inputs!$B$13,IF(9<=Inputs!$B$8,IF(Inputs!$B$12>0,MAX(MIN(NORM.INV(RAND(),LOOKUP(X18,Inputs!$J$6:$J$9,Inputs!$G$6:$G$9),LOOKUP(X18,Inputs!$J$6:$J$9,Inputs!$H$6:$H$9)),Inputs!$B$12),-Inputs!$B$12),NORM.INV(RAND(),LOOKUP(X18,Inputs!$J$6:$J$9,Inputs!$G$6:$G$9),LOOKUP(X18,Inputs!$J$6:$J$9,Inputs!$H$6:$H$9))),0),"" ) | O18: =IF($A18<=Inputs!$B$13,IF(10<=Inputs!$B$8,IF(Inputs!$B$12>0,MAX(MIN(NORM.INV(RAND(),LOOKUP(Y18,Inputs!$J$6:$J$9,Inputs!$G$6:$G$9),LOOKUP(Y18,Inputs!$J$6:$J$9,Inputs!$H$6:$H$9)),Inputs!$B$12),-Inputs!$B$12),NORM.INV(RAND(),LOOKUP(Y18,Inputs!$J$6:$J$9,Inputs!$G$6:$G$9),LOOKUP(Y18,Inputs!$J$6:$J$9,Inputs!$H$6:$H$9))),0),"" ) | P18: =IF($A18<=Inputs!$B$13,RAND(),"") | Q18: =IF($A18<=Inputs!$B$13,RAND(),"") | R18: =IF($A18<=Inputs!$B$13,RAND(),"") | S18: =IF($A18<=Inputs!$B$13,RAND(),"") | T18: =IF($A18<=Inputs!$B$13,RAND(),"") | U18: =IF($A18<=Inputs!$B$13,RAND(),"") | V18: =IF($A18<=Inputs!$B$13,RAND(),"") | W18: =IF($A18<=Inputs!$B$13,RAND(),"") | ... Y18: =IF($A18<=Inputs!$B$13,RAND(),"")
A19: 14 | B19: =IF($A19<=Inputs!$B$13,IF(Inputs!$B$8>0,SUM(F19:O19)/Inputs!$B$8,0),"") | C19: =IF($A19<=Inputs!$B$13,B19/100,"") | D19: =IF($A19<=Inputs!$B$13,C19*Inputs!$B$7,"") | E19: =IF($A19<=Inputs!$B$13,IF(D19>0,1,0),"") | F19: =IF($A19<=Inputs!$B$13,IF(1<=Inputs!$B$8,IF(Inputs!$B$12>0,MAX(MIN(NORM.INV(RAND(),LOOKUP(P19,Inputs!$J$6:$J$9,Inputs!$G$6:$G$9),LOOKUP(P19,Inputs!$J$6:$J$9,Inputs!$H$6:$H$9)),Inputs!$B$12),-Inputs!$B$12),NORM.INV(RAND(),LOOKUP(P19,Inputs!$J$6:$J$9,Inputs!$G$6:$G$9),LOOKUP(P19,Inputs!$J$6:$J$9,Inputs!$H$6:$H$9))),0),"" ) | G19: =IF($A19<=Inputs!$B$13,IF(2<=Inputs!$B$8,IF(Inputs!$B$12>0,MAX(MIN(NORM.INV(RAND(),LOOKUP(Q19,Inputs!$J$6:$J$9,Inputs!$G$6:$G$9),LOOKUP(Q19,Inputs!$J$6:$J$9,Inputs!$H$6:$H$9)),Inputs!$B$12),-Inputs!$B$12),NORM.INV(RAND(),LOOKUP(Q19,Inputs!$J$6:$J$9,Inputs!$G$6:$G$9),LOOKUP(Q19,Inputs!$J$6:$J$9,Inputs!$H$6:$H$9))),0),"" ) | H19: =IF($A19<=Inputs!$B$13,IF(3<=Inputs!$B$8,IF(Inputs!$B$12>0,MAX(MIN(NORM.INV(RAND(),LOOKUP(R19,Inputs!$J$6:$J$9,Inputs!$G$6:$G$9),LOOKUP(R19,Inputs!$J$6:$J$9,Inputs!$H$6:$H$9)),Inputs!$B$12),-Inputs!$B$12),NORM.INV(RAND(),LOOKUP(R19,Inputs!$J$6:$J$9,Inputs!$G$6:$G$9),LOOKUP(R19,Inputs!$J$6:$J$9,Inputs!$H$6:$H$9))),0),"" ) | I19: =IF($A19<=Inputs!$B$13,IF(4<=Inputs!$B$8,IF(Inputs!$B$12>0,MAX(MIN(NORM.INV(RAND(),LOOKUP(S19,Inputs!$J$6:$J$9,Inputs!$G$6:$G$9),LOOKUP(S19,Inputs!$J$6:$J$9,Inputs!$H$6:$H$9)),Inputs!$B$12),-Inputs!$B$12),NORM.INV(RAND(),LOOKUP(S19,Inputs!$J$6:$J$9,Inputs!$G$6:$G$9),LOOKUP(S19,Inputs!$J$6:$J$9,Inputs!$H$6:$H$9))),0),"" ) | J19: =IF($A19<=Inputs!$B$13,IF(5<=Inputs!$B$8,IF(Inputs!$B$12>0,MAX(MIN(NORM.INV(RAND(),LOOKUP(T19,Inputs!$J$6:$J$9,Inputs!$G$6:$G$9),LOOKUP(T19,Inputs!$J$6:$J$9,Inputs!$H$6:$H$9)),Inputs!$B$12),-Inputs!$B$12),NORM.INV(RAND(),LOOKUP(T19,Inputs!$J$6:$J$9,Inputs!$G$6:$G$9),LOOKUP(T19,Inputs!$J$6:$J$9,Inputs!$H$6:$H$9))),0),"" ) | K19: =IF($A19<=Inputs!$B$13,IF(6<=Inputs!$B$8,IF(Inputs!$B$12>0,MAX(MIN(NORM.INV(RAND(),LOOKUP(U19,Inputs!$J$6:$J$9,Inputs!$G$6:$G$9),LOOKUP(U19,Inputs!$J$6:$J$9,Inputs!$H$6:$H$9)),Inputs!$B$12),-Inputs!$B$12),NORM.INV(RAND(),LOOKUP(U19,Inputs!$J$6:$J$9,Inputs!$G$6:$G$9),LOOKUP(U19,Inputs!$J$6:$J$9,Inputs!$H$6:$H$9))),0),"" ) | L19: =IF($A19<=Inputs!$B$13,IF(7<=Inputs!$B$8,IF(Inputs!$B$12>0,MAX(MIN(NORM.INV(RAND(),LOOKUP(V19,Inputs!$J$6:$J$9,Inputs!$G$6:$G$9),LOOKUP(V19,Inputs!$J$6:$J$9,Inputs!$H$6:$H$9)),Inputs!$B$12),-Inputs!$B$12),NORM.INV(RAND(),LOOKUP(V19,Inputs!$J$6:$J$9,Inputs!$G$6:$G$9),LOOKUP(V19,Inputs!$J$6:$J$9,Inputs!$H$6:$H$9))),0),"" ) | M19: =COUNTIFS($B$6:$B$5005,">="&K19,$B$6:$B$5005,"<"&L19) | N19: =IF($A19<=Inputs!$B$13,IF(9<=Inputs!$B$8,IF(Inputs!$B$12>0,MAX(MIN(NORM.INV(RAND(),LOOKUP(X19,Inputs!$J$6:$J$9,Inputs!$G$6:$G$9),LOOKUP(X19,Inputs!$J$6:$J$9,Inputs!$H$6:$H$9)),Inputs!$B$12),-Inputs!$B$12),NORM.INV(RAND(),LOOKUP(X19,Inputs!$J$6:$J$9,Inputs!$G$6:$G$9),LOOKUP(X19,Inputs!$J$6:$J$9,Inputs!$H$6:$H$9))),0),"" ) | O19: =IF($A19<=Inputs!$B$13,IF(10<=Inputs!$B$8,IF(Inputs!$B$12>0,MAX(MIN(NORM.INV(RAND(),LOOKUP(Y19,Inputs!$J$6:$J$9,Inputs!$G$6:$G$9),LOOKUP(Y19,Inputs!$J$6:$J$9,Inputs!$H$6:$H$9)),Inputs!$B$12),-Inputs!$B$12),NORM.INV(RAND(),LOOKUP(Y19,Inputs!$J$6:$J$9,Inputs!$G$6:$G$9),LOOKUP(Y19,Inputs!$J$6:$J$9,Inputs!$H$6:$H$9))),0),"" ) | P19: =IF($A19<=Inputs!$B$13,RAND(),"") | Q19: =IF($A19<=Inputs!$B$13,RAND(),"") | R19: =IF($A19<=Inputs!$B$13,RAND(),"") | S19: =IF($A19<=Inputs!$B$13,RAND(),"") | T19: =IF($A19<=Inputs!$B$13,RAND(),"") | U19: =IF($A19<=Inputs!$B$13,RAND(),"") | V19: =IF($A19<=Inputs!$B$13,RAND(),"") | W19: =IF($A19<=Inputs!$B$13,RAND(),"") | ... Y19: =IF($A19<=Inputs!$B$13,RAND(),"")
A20: 15 | B20: =IF($A20<=Inputs!$B$13,IF(Inputs!$B$8>0,SUM(F20:O20)/Inputs!$B$8,0),"") | C20: =IF($A20<=Inputs!$B$13,B20/100,"") | D20: =IF($A20<=Inputs!$B$13,C20*Inputs!$B$7,"") | E20: =IF($A20<=Inputs!$B$13,IF(D20>0,1,0),"") | F20: =IF($A20<=Inputs!$B$13,IF(1<=Inputs!$B$8,IF(Inputs!$B$12>0,MAX(MIN(NORM.INV(RAND(),LOOKUP(P20,Inputs!$J$6:$J$9,Inputs!$G$6:$G$9),LOOKUP(P20,Inputs!$J$6:$J$9,Inputs!$H$6:$H$9)),Inputs!$B$12),-Inputs!$B$12),NORM.INV(RAND(),LOOKUP(P20,Inputs!$J$6:$J$9,Inputs!$G$6:$G$9),LOOKUP(P20,Inputs!$J$6:$J$9,Inputs!$H$6:$H$9))),0),"" ) | G20: =IF($A20<=Inputs!$B$13,IF(2<=Inputs!$B$8,IF(Inputs!$B$12>0,MAX(MIN(NORM.INV(RAND(),LOOKUP(Q20,Inputs!$J$6:$J$9,Inputs!$G$6:$G$9),LOOKUP(Q20,Inputs!$J$6:$J$9,Inputs!$H$6:$H$9)),Inputs!$B$12),-Inputs!$B$12),NORM.INV(RAND(),LOOKUP(Q20,Inputs!$J$6:$J$9,Inputs!$G$6:$G$9),LOOKUP(Q20,Inputs!$J$6:$J$9,Inputs!$H$6:$H$9))),0),"" ) | H20: =IF($A20<=Inputs!$B$13,IF(3<=Inputs!$B$8,IF(Inputs!$B$12>0,MAX(MIN(NORM.INV(RAND(),LOOKUP(R20,Inputs!$J$6:$J$9,Inputs!$G$6:$G$9),LOOKUP(R20,Inputs!$J$6:$J$9,Inputs!$H$6:$H$9)),Inputs!$B$12),-Inputs!$B$12),NORM.INV(RAND(),LOOKUP(R20,Inputs!$J$6:$J$9,Inputs!$G$6:$G$9),LOOKUP(R20,Inputs!$J$6:$J$9,Inputs!$H$6:$H$9))),0),"" ) | I20: =IF($A20<=Inputs!$B$13,IF(4<=Inputs!$B$8,IF(Inputs!$B$12>0,MAX(MIN(NORM.INV(RAND(),LOOKUP(S20,Inputs!$J$6:$J$9,Inputs!$G$6:$G$9),LOOKUP(S20,Inputs!$J$6:$J$9,Inputs!$H$6:$H$9)),Inputs!$B$12),-Inputs!$B$12),NORM.INV(RAND(),LOOKUP(S20,Inputs!$J$6:$J$9,Inputs!$G$6:$G$9),LOOKUP(S20,Inputs!$J$6:$J$9,Inputs!$H$6:$H$9))),0),"" ) | J20: =IF($A20<=Inputs!$B$13,IF(5<=Inputs!$B$8,IF(Inputs!$B$12>0,MAX(MIN(NORM.INV(RAND(),LOOKUP(T20,Inputs!$J$6:$J$9,Inputs!$G$6:$G$9),LOOKUP(T20,Inputs!$J$6:$J$9,Inputs!$H$6:$H$9)),Inputs!$B$12),-Inputs!$B$12),NORM.INV(RAND(),LOOKUP(T20,Inputs!$J$6:$J$9,Inputs!$G$6:$G$9),LOOKUP(T20,Inputs!$J$6:$J$9,Inputs!$H$6:$H$9))),0),"" ) | K20: =IF($A20<=Inputs!$B$13,IF(6<=Inputs!$B$8,IF(Inputs!$B$12>0,MAX(MIN(NORM.INV(RAND(),LOOKUP(U20,Inputs!$J$6:$J$9,Inputs!$G$6:$G$9),LOOKUP(U20,Inputs!$J$6:$J$9,Inputs!$H$6:$H$9)),Inputs!$B$12),-Inputs!$B$12),NORM.INV(RAND(),LOOKUP(U20,Inputs!$J$6:$J$9,Inputs!$G$6:$G$9),LOOKUP(U20,Inputs!$J$6:$J$9,Inputs!$H$6:$H$9))),0),"" ) | L20: =IF($A20<=Inputs!$B$13,IF(7<=Inputs!$B$8,IF(Inputs!$B$12>0,MAX(MIN(NORM.INV(RAND(),LOOKUP(V20,Inputs!$J$6:$J$9,Inputs!$G$6:$G$9),LOOKUP(V20,Inputs!$J$6:$J$9,Inputs!$H$6:$H$9)),Inputs!$B$12),-Inputs!$B$12),NORM.INV(RAND(),LOOKUP(V20,Inputs!$J$6:$J$9,Inputs!$G$6:$G$9),LOOKUP(V20,Inputs!$J$6:$J$9,Inputs!$H$6:$H$9))),0),"" ) | M20: =COUNTIFS($B$6:$B$5005,">="&K20,$B$6:$B$5005,"<"&L20) | N20: =IF($A20<=Inputs!$B$13,IF(9<=Inputs!$B$8,IF(Inputs!$B$12>0,MAX(MIN(NORM.INV(RAND(),LOOKUP(X20,Inputs!$J$6:$J$9,Inputs!$G$6:$G$9),LOOKUP(X20,Inputs!$J$6:$J$9,Inputs!$H$6:$H$9)),Inputs!$B$12),-Inputs!$B$12),NORM.INV(RAND(),LOOKUP(X20,Inputs!$J$6:$J$9,Inputs!$G$6:$G$9),LOOKUP(X20,Inputs!$J$6:$J$9,Inputs!$H$6:$H$9))),0),"" ) | O20: =IF($A20<=Inputs!$B$13,IF(10<=Inputs!$B$8,IF(Inputs!$B$12>0,MAX(MIN(NORM.INV(RAND(),LOOKUP(Y20,Inputs!$J$6:$J$9,Inputs!$G$6:$G$9),LOOKUP(Y20,Inputs!$J$6:$J$9,Inputs!$H$6:$H$9)),Inputs!$B$12),-Inputs!$B$12),NORM.INV(RAND(),LOOKUP(Y20,Inputs!$J$6:$J$9,Inputs!$G$6:$G$9),LOOKUP(Y20,Inputs!$J$6:$J$9,Inputs!$H$6:$H$9))),0),"" ) | P20: =IF($A20<=Inputs!$B$13,RAND(),"") | Q20: =IF($A20<=Inputs!$B$13,RAND(),"") | R20: =IF($A20<=Inputs!$B$13,RAND(),"") | S20: =IF($A20<=Inputs!$B$13,RAND(),"") | T20: =IF($A20<=Inputs!$B$13,RAND(),"") | U20: =IF($A20<=Inputs!$B$13,RAND(),"") | V20: =IF($A20<=Inputs!$B$13,RAND(),"") | W20: =IF($A20<=Inputs!$B$13,RAND(),"") | ... Y20: =IF($A20<=Inputs!$B$13,RAND(),"")
